Workbook

Sheet README
A1: SLIC Scoring Workbook
A3: Purpose | B3: This workbook is the operational source of truth for the global SLIC city ranking. Enter or import data into Country_Context and City_Inputs, then review Scores, Leaderboard, Region_Comparison, and the Thai-specific scaffold.
A4: Official formula | B4: SLIC(c) = 0.25 Pressure + 0.22 Viability + 0.18 Capability + 0.15 Community + 0.20 Creative
A5: Disposable income term | B5: DI_ppp = ((gross_income x (1 - tax_rate)) - rent - utilities - transit - internet - food) / ppp_private_consumption
A6: Normalization | B6: Each scored input is winsorized at the 5th and 95th percentiles, then converted to a 0-100 score. Harmful variables such as crime, debt, suicide, PM2.5, and administrative friction are reverse-scored.
A7: Coverage rules | B7: A city is Ranked only when overall weighted coverage is at least 50% and every pillar clears the 35% minimum. Coverage grades: A >= 75%, B = 50-74%, C = 35-49%, below 35% = Watchlist.
A8: Source hierarchy | B8: Tier 1 city/metro official data > Tier 2 subnational official data > Tier 3 national and international official data > Tier 4 audited secondary and experimental layers.
A9: Doctrinal rule: safety | B9: Safety is scored by harm and victimization outcomes, never by camera count or visible control hardware.
A10: Doctrinal rule: tolerance | B10: Tolerance is scored through low-friction coexistence and real personal freedom, not symbolic branding proxies.
A11: Doctrinal rule: visitor flows | B11: Visitor flow is contextual only. It should be reviewed against crime, civic strain, and public-life quality rather than treated as an automatic positive.
A12: Country context | B12: GDP per capita PPP, GDP growth, Gini coefficient, PPP private consumption, and user-supplied tax rate are visible in Country_Context. GDP terms are capped context inputs, not headline determinants.
A13: How tax works | B13: Populate tax_rate_assumption in Country_Context as a decimal such as 0.18. City_Inputs pulls that value automatically into tax_rate_context and recomputes di_ppp_raw.
A14: Region comparison | B14: Region_Comparison summarizes ranked city counts and average scores by cohort so Europe, Asia, the Americas, Africa, the Middle East, and Oceania can be compared cleanly.
A15: Thai companion | B15: Thai_Ranking_Scaffold is a separate sheet for a Thailand-only ranking. It emphasizes province GDP per capita, pollution, hospitals, schools, infrastructure, income, longevity, and competitiveness.
A18: Coverage thresholds
A19: ranked_min_overall | B19: 0.5
A20: ranked_min_pillar | B20: 0.35
A21: grade_a_min | B21: 0.75
A22: grade_b_min | B22: 0.5
A23: grade_c_min | B23: 0.35
A26: Source tiers
A27: Tier 1 | B27: City and metro official data | C27: Open-data portals, utility regulators, transit feeds, hospital quality releases, and city statistical offices.
A28: Tier 2 | B28: State, province, and subnational official data | C28: Regional statistical offices, metropolitan observatories, and subnational administrative datasets.
A29: Tier 3 | B29: National and international official datasets | C29: World Bank, WHO, ILO, UNESCO UIS, OECD, WIPO, and WHO/UNICEF JMP.
A30: Tier 4 | B30: Audited secondary and experimental layers | C30: OpenAQ, M-Lab, social listening, crowdsourced cost layers, and city testimony with visible caveats.

Sheet Metric_Catalog
A1: metric_id | B1: metric_name | C1: pillar_id | D1: pillar_name | E1: pillar_weight | F1: metric_weight | G1: directionality | H1: scoring_role | I1: requiredness | J1: data_level | K1: source_priority | L1: workbook_input | M1: notes
A2: disposable_income_ppp | B2: Tax-adjusted PPP disposable income | C2: pressure | D2: Growth | E2: 25 | F2: 9 | G2: positive | H2: scored | I2: core | J2: city_or_metro_with_country_context | K2: Tier 1 city/metro > Tier 2 subnational > Tier 3 national/international > Tier 4 audited secondary | L2: di_ppp_raw | M2: Derived from gross income, tax, rent, utilities, transit, internet, food, and PPP private consumption.
A3: housing_burden | B3: Housing burden | C3: pressure | D3: Growth | E3: 25 | F3: 5 | G3: negative | H3: scored | I3: core | J3: city_or_metro | K3: Tier 1 city/metro > Tier 2 subnational > Tier 3 national/international > Tier 4 audited secondary | L3: housing_burden_raw | M3: Higher rent or housing cost share scores worse.
A4: household_debt_burden | B4: Household debt burden | C4: pressure | D4: Growth | E4: 25 | F4: 4 | G4: negative | H4: scored | I4: core | J4: city_with_country_proxy_fallback | K4: Tier 1 city/metro > Tier 2 subnational > Tier 3 country debt proxy > Tier 4 audited secondary | L4: household_debt_effective_raw | M4: Uses country proxy when city debt burden is unavailable.
A5: working_time_pressure | B5: Working time pressure | C5: pressure | D5: Growth | E5: 25 | F5: 4 | G5: negative | H5: scored | I5: core | J5: city_or_metro_with_subnational_fallback | K5: Tier 1 city/metro > Tier 2 subnational > Tier 3 ILO/national > Tier 4 audited secondary | L5: working_time_pressure_raw | M5: Higher weekly-hours and overwork prevalence score worse.
A6: suicide_mental_strain | B6: Suicide and severe mental strain | C6: pressure | D6: Growth | E6: 25 | F6: 5 | G6: negative | H6: scored | I6: core | J6: city_or_metro_with_subnational_fallback | K6: Tier 1 city/metro > Tier 2 subnational > Tier 3 WHO/national > Tier 4 audited secondary | L6: suicide_mental_strain_raw | M6: Lower suicide or equivalent severe-strain rates score better. Weight increased to 5 to better capture mental wellbeing burden.
A7: personal_safety | B7: Personal safety | C7: viability | D7: Viability | E7: 22 | F7: 5 | G7: negative | H7: scored | I7: core | J7: city_or_metro | K7: Tier 1 city/metro > Tier 2 subnational > Tier 3 national/international > Tier 4 audited secondary | L7: personal_safety_raw | M7: Enter a harm-and-victimization index or rate. Camera counts do not score.
A8: transit_access_commute | B8: Transit access and commute burden | C8: viability | D8: Viability | E8: 22 | F8: 5 | G8: positive | H8: scored | I8: core | J8: city_or_metro | K8: Tier 1 city/metro > Tier 2 GTFS/subnational > Tier 3 national/international > Tier 4 audited secondary | L8: transit_access_commute_raw | M8: Enter a composite where better access and lower burden push the value upward.
A9: clean_air | B9: Clean air | C9: viability | D9: Viability | E9: 22 | F9: 4 | G9: negative | H9: scored | I9: core | J9: city_or_metro | K9: Tier 1 city/metro > Tier 3 WHO/OpenAQ/national > Tier 4 audited secondary | L9: clean_air_raw | M9: Lower PM2.5 or pollution exposure scores better.
A10: water_sanitation_utility | B10: Water, sanitation, and utility reliability | C10: viability | D10: Viability | E10: 22 | F10: 4 | G10: positive | H10: scored | I10: core | J10: city_or_metro_with_country_fallback | K10: Tier 1 city/metro > Tier 2 subnational > Tier 3 JMP/national > Tier 4 audited secondary | L10: water_sanitation_utility_raw | M10: Enter a composite where safer access and higher reliability score better.
A11: digital_infrastructure | B11: Digital infrastructure | C11: viability | D11: Viability | E11: 22 | F11: 4 | G11: positive | H11: scored | I11: core | J11: city_or_metro_with_country_fallback | K11: Tier 1 city/metro > Tier 2 subnational > Tier 3 OECD/World Bank/M-Lab > Tier 4 audited secondary | L11: digital_infrastructure_raw | M11: Higher broadband quality, affordability, and fibre readiness score better.
A12: climate_sunlight_livability | B12: Climate and sunlight livability | C12: viability | D12: Viability | E12: 22 | F12: 5 | G12: positive | H12: scored | I12: core | J12: city_or_metro | K12: Tier 1 city/metro climate data > Tier 3 WMO/national > Tier 4 audited secondary | L12: climate_sunlight_livability_raw | M12: Composite of annual sunshine hours, temperature comfort (distance from 22C optimum), and extreme weather frequency. Penalizes both extreme darkness (Nordic winter) and extreme heat (Gulf/desert). Higher = more livable climate.
A13: healthcare_quality | B13: Healthcare quality | C13: capability | D13: Capability | E13: 18 | F13: 8 | G13: positive | H13: scored | I13: core | J13: city_or_metro_with_country_context | K13: Tier 1 city/metro > Tier 2 subnational > Tier 3 WHO/OECD/national > Tier 4 audited secondary | L13: healthcare_quality_raw | M13: Higher effective-care access and outcome quality score better.
... A27: birth_rate_optimism | B27: Birth rate and societal optimism | C27: community | D27: Community | E27: 15 | F27: 4 | G27: positive | H27: scored | I27: core | J27: country_proxy_or_city | K27: Tier 1 city/metro > Tier 3 national/international | L27: birth_rate_optimism_raw | M27: Total fertility rate or crude birth rate as proxy for societal optimism and family-friendliness.

Sheet City_Universe
A1: city_id | B1: display_name | C1: fua_name | D1: country | E1: cohort | F1: city_type | G1: manifest_status | H1: inclusion_rationale
A2: th-bangkok | B2: Bangkok | C2: Bangkok Metropolitan Region | D2: Thailand | E2: Southeast Asia | F2: primary | G2: locked | H2: User anchor and regional benchmark for hospitality, economic dynamism, and affordability-pressure tradeoffs.
A3: sg-singapore | B3: Singapore | C3: Singapore | D3: Singapore | E3: Southeast Asia | F3: primary | G3: locked | H3: Global convenience benchmark included to test how systems quality interacts with pressure, cost, and meaning.
A4: my-kuala-lumpur | B4: Kuala Lumpur | C4: Klang Valley | D4: Malaysia | E4: Southeast Asia | F4: primary | G4: locked | H4: User anchor and regional economic core with strong competitiveness, connectivity, and mixed affordability.
A5: id-jakarta | B5: Jakarta | C5: Jakarta Metropolitan Area | D5: Indonesia | E5: Southeast Asia | F5: primary | G5: provisional | H5: Necessary Southeast Asian benchmark for scale, competitiveness, and infrastructure-pressure tradeoffs.
A6: ph-makati | B6: Makati | C6: Metro Manila Core Business District | D6: Philippines | E6: Southeast Asia | F6: primary | G6: provisional | H6: Metro-core Philippine test case included for business density, services, and lived-affordability stress.
A7: my-george-town | B7: George Town | C7: Penang Conurbation | D7: Malaysia | E7: Southeast Asia | F7: secondary | G7: locked | H7: User anchor for semiconductor economy, cultural texture, and secondary-city livability.
A8: th-phuket | B8: Phuket | C8: Phuket Island Urban Area | D8: Thailand | E8: Southeast Asia | F8: secondary | G8: locked | H8: User anchor and tourism-livability stress test for cost, safety, and service quality.
A9: th-chiang-mai | B9: Chiang Mai | C9: Chiang Mai Metropolitan Area | D9: Thailand | E9: Southeast Asia | F9: secondary | G9: locked | H9: User anchor for creativity, secondary-city ambition, and lifestyle viability.
A10: my-kuching | B10: Kuching | C10: Greater Kuching | D10: Malaysia | E10: Southeast Asia | F10: secondary | G10: locked | H10: User anchor included as a calmer secondary-city comparator with strong everyday livability appeal.
A11: my-kota-kinabalu | B11: Kota Kinabalu | C11: Kota Kinabalu Urban Area | D11: Malaysia | E11: Southeast Asia | F11: secondary | G11: provisional | H11: User anchor — nature tourism, safety, and affordable livability on Borneo's coast.
A12: my-melaka | B12: Melaka | C12: Melaka Urban Area | D12: Malaysia | E12: Southeast Asia | F12: secondary | G12: provisional | H12: User anchor — deep cultural heritage, food scene, and underrated livability.
... A158: vu-port-vila | B158: Port Vila | C158: Greater Port Vila | D158: Vanuatu | E158: Oceania | F158: primary | G158: provisional | H158: Reserve Pacific capital comparator added for tourism, climate exposure, and utility-reliability benchmarking.

Sheet Country_Context
A1: country | B1: gdp_per_capita_ppp | C1: gdp_growth | D1: gini_coefficient | E1: ppp_private_consumption | F1: tax_rate_assumption | G1: household_debt_proxy | H1: source_url | I1: source_tier | J1: update_date | K1: notes
A2: Thailand | B2: 24712.07 | C2: 2.5418 | D2: 33.5 | E2: 10.945576 | F2: 0.152577 | G2: 115.1054 | H2: https://api.worldbank.org/v2/country/THA/indicator/NY.GDP.PCAP.PP.CD?format=json&mrv=30 | https://api.worldbank.org/v2/country/THA/indicator/NY.GDP.MKTP.KD.ZG?format=json&mrv=30 | https://api.worldbank.org/v2/country/THA/indicator/SI.POV.GINI?format=json&mrv=30 | +3 more | I2: Tier 3 | J2: 2024-12-31 | K2: providers=world_bank; fields=gdp_per_capita_ppp, gdp_growth, gini_coefficient, ppp_private_consumption; +2 additional fields
A3: Singapore | B3: 150689.3 | C3: 4.388 | E3: 1.04203 | F3: 0.141917 | G3: 129.1908 | H3: https://api.worldbank.org/v2/country/SGP/indicator/NY.GDP.PCAP.PP.CD?format=json&mrv=30 | https://api.worldbank.org/v2/country/SGP/indicator/NY.GDP.MKTP.KD.ZG?format=json&mrv=30 | https://api.worldbank.org/v2/country/SGP/indicator/PA.NUS.PRVT.PP?format=json&mrv=30 | +2 more | I3: Tier 3 | J3: 2024-12-31 | K3: providers=world_bank; fields=gdp_per_capita_ppp, gdp_growth, ppp_private_consumption, tax_rate_assumption; +1 additional fields
A4: Malaysia | B4: 38779.28 | C4: 5.1055 | D4: 40.7 | E4: 1.449227 | F4: 0.125648 | G4: 116.0773 | H4: https://api.worldbank.org/v2/country/MYS/indicator/NY.GDP.PCAP.PP.CD?format=json&mrv=30 | https://api.worldbank.org/v2/country/MYS/indicator/NY.GDP.MKTP.KD.ZG?format=json&mrv=30 | https://api.worldbank.org/v2/country/MYS/indicator/SI.POV.GINI?format=json&mrv=30 | +3 more | I4: Tier 3 | J4: 2024-12-31 | K4: providers=world_bank; fields=gdp_per_capita_ppp, gdp_growth, gini_coefficient, ppp_private_consumption; +2 additional fields
A5: Indonesia | B5: 16448.28 | C5: 5.0303 | D5: 34.9 | E5: 5104.9843 | F5: 0.110578 | G5: 31.7861 | H5: https://api.worldbank.org/v2/country/IDN/indicator/NY.GDP.PCAP.PP.CD?format=json&mrv=30 | https://api.worldbank.org/v2/country/IDN/indicator/NY.GDP.MKTP.KD.ZG?format=json&mrv=30 | https://api.worldbank.org/v2/country/IDN/indicator/SI.POV.GINI?format=json&mrv=30 | +3 more | I5: Tier 3 | J5: 2024-12-31 | K5: providers=world_bank; fields=gdp_per_capita_ppp, gdp_growth, gini_coefficient, ppp_private_consumption; +2 additional fields
A6: Philippines | B6: 11794.14 | C6: 5.692 | D6: 39.3 | E6: 20.743506 | F6: 0.141044 | G6: 49.8137 | H6: https://api.worldbank.org/v2/country/PHL/indicator/NY.GDP.PCAP.PP.CD?format=json&mrv=30 | https://api.worldbank.org/v2/country/PHL/indicator/NY.GDP.MKTP.KD.ZG?format=json&mrv=30 | https://api.worldbank.org/v2/country/PHL/indicator/SI.POV.GINI?format=json&mrv=30 | +3 more | I6: Tier 3 | J6: 2024-12-31 | K6: providers=world_bank; fields=gdp_per_capita_ppp, gdp_growth, gini_coefficient, ppp_private_consumption; +2 additional fields
A7: Taiwan | K7: Populate official country context inputs before ranking.
A8: South Korea | B8: 61051.35 | C8: 2.0036 | D8: 32.9 | E8: 872.46874 | F8: 0.145991 | G8: 160.3472 | H8: https://api.worldbank.org/v2/country/KOR/indicator/NY.GDP.PCAP.PP.CD?format=json&mrv=30 | https://api.worldbank.org/v2/country/KOR/indicator/NY.GDP.MKTP.KD.ZG?format=json&mrv=30 | https://api.worldbank.org/v2/country/KOR/indicator/SI.POV.GINI?format=json&mrv=30 | +3 more | I8: Tier 3 | J8: 2024-12-31 | K8: providers=world_bank; fields=gdp_per_capita_ppp, gdp_growth, gini_coefficient, ppp_private_consumption; +2 additional fields
A9: China | B9: 27104.87 | C9: 4.9774 | D9: 36 | E9: 3.550789 | F9: 0.076382 | G9: 194.166 | H9: https://api.worldbank.org/v2/country/CHN/indicator/NY.GDP.PCAP.PP.CD?format=json&mrv=30 | https://api.worldbank.org/v2/country/CHN/indicator/NY.GDP.MKTP.KD.ZG?format=json&mrv=30 | https://api.worldbank.org/v2/country/CHN/indicator/SI.POV.GINI?format=json&mrv=30 | +3 more | I9: Tier 3 | J9: 2024-12-31 | K9: providers=world_bank; fields=gdp_per_capita_ppp, gdp_growth, gini_coefficient, ppp_private_consumption; +2 additional fields
A10: Japan | B10: 52039.17 | C10: 0.1043 | D10: 32.3 | E10: 99.384798 | G10: 123.1289 | H10: https://api.worldbank.org/v2/country/JPN/indicator/NY.GDP.PCAP.PP.CD?format=json&mrv=30 | https://api.worldbank.org/v2/country/JPN/indicator/NY.GDP.MKTP.KD.ZG?format=json&mrv=30 | https://api.worldbank.org/v2/country/JPN/indicator/SI.POV.GINI?format=json&mrv=30 | +2 more | I10: Tier 3 | J10: 2024-12-31 | K10: providers=world_bank; fields=gdp_per_capita_ppp, gdp_growth, gini_coefficient, ppp_private_consumption; +1 additional fields
A11: India | B11: 11159.99 | C11: 6.4948 | D11: 25.5 | E11: 19.896916 | F11: 0.067344 | G11: 50.1422 | H11: https://api.worldbank.org/v2/country/IND/indicator/NY.GDP.PCAP.PP.CD?format=json&mrv=30 | https://api.worldbank.org/v2/country/IND/indicator/NY.GDP.MKTP.KD.ZG?format=json&mrv=30 | https://api.worldbank.org/v2/country/IND/indicator/SI.POV.GINI?format=json&mrv=30 | +3 more | I11: Tier 3 | J11: 2024-12-31 | K11: providers=world_bank; fields=gdp_per_capita_ppp, gdp_growth, gini_coefficient, ppp_private_consumption; +2 additional fields
A12: Sri Lanka | B12: 15632.59 | C12: 5.0087 | D12: 37.7 | E12: 87.489315 | F12: 0.099219 | G12: 46.8716 | H12: https://api.worldbank.org/v2/country/LKA/indicator/NY.GDP.PCAP.PP.CD?format=json&mrv=30 | https://api.worldbank.org/v2/country/LKA/indicator/NY.GDP.MKTP.KD.ZG?format=json&mrv=30 | https://api.worldbank.org/v2/country/LKA/indicator/SI.POV.GINI?format=json&mrv=30 | +3 more | I12: Tier 3 | J12: 2024-12-31 | K12: providers=world_bank; fields=gdp_per_capita_ppp, gdp_growth, gini_coefficient, ppp_private_consumption; +2 additional fields
A13: Bangladesh | B13: 9646.77 | C13: 4.2233 | D13: 30.9 | E13: 32.990539 | F13: 0.076424 | G13: 35.7061 | H13: https://api.worldbank.org/v2/country/BGD/indicator/NY.GDP.PCAP.PP.CD?format=json&mrv=30 | https://api.worldbank.org/v2/country/BGD/indicator/NY.GDP.MKTP.KD.ZG?format=json&mrv=30 | https://api.worldbank.org/v2/country/BGD/indicator/SI.POV.GINI?format=json&mrv=30 | +3 more | I13: Tier 3 | J13: 2024-12-31 | K13: providers=world_bank; fields=gdp_per_capita_ppp, gdp_growth, gini_coefficient, ppp_private_consumption; +2 additional fields
A14: Pakistan | B14: 6252.12 | C14: 3.049 | D14: 29.6 | E14: 64.860994 | G14: 11.3901 | H14: https://api.worldbank.org/v2/country/PAK/indicator/NY.GDP.PCAP.PP.CD?format=json&mrv=30 | https://api.worldbank.org/v2/country/PAK/indicator/NY.GDP.MKTP.KD.ZG?format=json&mrv=30 | https://api.worldbank.org/v2/country/PAK/indicator/SI.POV.GINI?format=json&mrv=30 | +2 more | I14: Tier 3 | J14: 2024-12-31 | K14: providers=world_bank; fields=gdp_per_capita_ppp, gdp_growth, gini_coefficient, ppp_private_consumption; +1 additional fields
A15: Nepal | B15: 5736.62 | C15: 3.6654 | D15: 30 | E15: 35.285741 | F15: 0.139449 | G15: 91.9385 | H15: https://api.worldbank.org/v2/country/NPL/indicator/NY.GDP.PCAP.PP.CD?format=json&mrv=30 | https://api.worldbank.org/v2/country/NPL/indicator/NY.GDP.MKTP.KD.ZG?format=json&mrv=30 | https://api.worldbank.org/v2/country/NPL/indicator/SI.POV.GINI?format=json&mrv=30 | +3 more | I15: Tier 3 | J15: 2024-12-31 | K15: providers=world_bank; fields=gdp_per_capita_ppp, gdp_growth, gini_coefficient, ppp_private_consumption; +2 additional fields
A16: Bhutan | B16: 16215.15 | C16: 4.6322 | D16: 28.5 | E16: 20.878112 | F16: 0.122846 | G16: 51.8935 | H16: https://api.worldbank.org/v2/country/BTN/indicator/NY.GDP.PCAP.PP.CD?format=json&mrv=30 | https://api.worldbank.org/v2/country/BTN/indicator/NY.GDP.MKTP.KD.ZG?format=json&mrv=30 | https://api.worldbank.org/v2/country/BTN/indicator/SI.POV.GINI?format=json&mrv=30 | +3 more | I16: Tier 3 | J16: 2024-12-31 | K16: providers=world_bank; fields=gdp_per_capita_ppp, gdp_growth, gini_coefficient, ppp_private_consumption; +2 additional fields
A17: Maldives | B17: 26182.78 | C17: 3.4944 | D17: 29.3 | E17: 9.455282 | F17: 0.194532 | G17: 31.5415 | H17: https://api.worldbank.org/v2/country/MDV/indicator/NY.GDP.PCAP.PP.CD?format=json&mrv=30 | https://api.worldbank.org/v2/country/MDV/indicator/NY.GDP.MKTP.KD.ZG?format=json&mrv=30 | https://api.worldbank.org/v2/country/MDV/indicator/SI.POV.GINI?format=json&mrv=30 | +3 more | I17: Tier 3 | J17: 2024-12-31 | K17: providers=world_bank; fields=gdp_per_capita_ppp, gdp_growth, gini_coefficient, ppp_private_consumption; +2 additional fields
A18: France | B18: 62556.92 | C18: 1.1905 | D18: 31.8 | E18: 0.716934 | F18: 0.23077 | G18: 103.9081 | H18: https://api.worldbank.org/v2/country/FRA/indicator/NY.GDP.PCAP.PP.CD?format=json&mrv=30 | https://api.worldbank.org/v2/country/FRA/indicator/NY.GDP.MKTP.KD.ZG?format=json&mrv=30 | https://api.worldbank.org/v2/country/FRA/indicator/SI.POV.GINI?format=json&mrv=30 | +3 more | I18: Tier 3 | J18: 2024-12-31 | K18: providers=world_bank; fields=gdp_per_capita_ppp, gdp_growth, gini_coefficient, ppp_private_consumption; +2 additional fields
A19: Austria | B19: 73911.44 | C19: -0.6591 | D19: 31.2 | E19: 0.720487 | F19: 0.256407 | G19: 81.4953 | H19: https://api.worldbank.org/v2/country/AUT/indicator/NY.GDP.PCAP.PP.CD?format=json&mrv=30 | https://api.worldbank.org/v2/country/AUT/indicator/NY.GDP.MKTP.KD.ZG?format=json&mrv=30 | https://api.worldbank.org/v2/country/AUT/indicator/SI.POV.GINI?format=json&mrv=30 | +3 more | I19: Tier 3 | J19: 2024-12-31 | K19: providers=world_bank; fields=gdp_per_capita_ppp, gdp_growth, gini_coefficient, ppp_private_consumption; +2 additional fields
A20: Switzerland | B20: 96497.69 | C20: 1.3023 | D20: 33.8 | E20: 1.062369 | F20: 0.090036 | G20: 170.3782 | H20: https://api.worldbank.org/v2/country/CHE/indicator/NY.GDP.PCAP.PP.CD?format=json&mrv=30 | https://api.worldbank.org/v2/country/CHE/indicator/NY.GDP.MKTP.KD.ZG?format=json&mrv=30 | https://api.worldbank.org/v2/country/CHE/indicator/SI.POV.GINI?format=json&mrv=30 | +3 more | I20: Tier 3 | J20: 2024-12-31 | K20: providers=world_bank; fields=gdp_per_capita_ppp, gdp_growth, gini_coefficient, ppp_private_consumption; +2 additional fields
A21: Netherlands | B21: 86173.63 | C21: 1.081 | D21: 25.7 | E21: 0.74195 | F21: 0.25254 | G21: 82.3297 | H21: https://api.worldbank.org/v2/country/NLD/indicator/NY.GDP.PCAP.PP.CD?format=json&mrv=30 | https://api.worldbank.org/v2/country/NLD/indicator/NY.GDP.MKTP.KD.ZG?format=json&mrv=30 | https://api.worldbank.org/v2/country/NLD/indicator/SI.POV.GINI?format=json&mrv=30 | +3 more | I21: Tier 3 | J21: 2024-12-31 | K21: providers=world_bank; fields=gdp_per_capita_ppp, gdp_growth, gini_coefficient, ppp_private_consumption; +2 additional fields
A22: Denmark | B22: 81878.23 | C22: 3.4778 | D22: 29.9 | E22: 6.764411 | F22: 0.315935 | G22: 144.0931 | H22: https://api.worldbank.org/v2/country/DNK/indicator/NY.GDP.PCAP.PP.CD?format=json&mrv=30 | https://api.worldbank.org/v2/country/DNK/indicator/NY.GDP.MKTP.KD.ZG?format=json&mrv=30 | https://api.worldbank.org/v2/country/DNK/indicator/SI.POV.GINI?format=json&mrv=30 | +3 more | I22: Tier 3 | J22: 2024-12-31 | K22: providers=world_bank; fields=gdp_per_capita_ppp, gdp_growth, gini_coefficient, ppp_private_consumption; +2 additional fields
A23: Italy | B23: 62014.27 | C23: 0.6927 | D23: 34.3 | E23: 0.625157 | F23: 0.24708 | G23: 59.3116 | H23: https://api.worldbank.org/v2/country/ITA/indicator/NY.GDP.PCAP.PP.CD?format=json&mrv=30 | https://api.worldbank.org/v2/country/ITA/indicator/NY.GDP.MKTP.KD.ZG?format=json&mrv=30 | https://api.worldbank.org/v2/country/ITA/indicator/SI.POV.GINI?format=json&mrv=30 | +3 more | I23: Tier 3 | J23: 2024-12-31 | K23: providers=world_bank; fields=gdp_per_capita_ppp, gdp_growth, gini_coefficient, ppp_private_consumption; +2 additional fields
A24: Portugal | B24: 51679.89 | C24: 2.1397 | D24: 33.9 | E24: 0.558749 | F24: 0.226188 | G24: 77.1375 | H24: https://api.worldbank.org/v2/country/PRT/indicator/NY.GDP.PCAP.PP.CD?format=json&mrv=30 | https://api.worldbank.org/v2/country/PRT/indicator/NY.GDP.MKTP.KD.ZG?format=json&mrv=30 | https://api.worldbank.org/v2/country/PRT/indicator/SI.POV.GINI?format=json&mrv=30 | +3 more | I24: Tier 3 | J24: 2024-12-31 | K24: providers=world_bank; fields=gdp_per_capita_ppp, gdp_growth, gini_coefficient, ppp_private_consumption; +2 additional fields
A25: Estonia | B25: 49968.71 | C25: -0.09 | D25: 30.7 | E25: 0.646078 | F25: 0.21329 | G25: 60.5329 | H25: https://api.worldbank.org/v2/country/EST/indicator/NY.GDP.PCAP.PP.CD?format=json&mrv=30 | https://api.worldbank.org/v2/country/EST/indicator/NY.GDP.MKTP.KD.ZG?format=json&mrv=30 | https://api.worldbank.org/v2/country/EST/indicator/SI.POV.GINI?format=json&mrv=30 | +3 more | I25: Tier 3 | J25: 2024-12-31 | K25: providers=world_bank; fields=gdp_per_capita_ppp, gdp_growth, gini_coefficient, ppp_private_consumption; +2 additional fields
A26: Finland | B26: 65378.38 | C26: 0.4162 | D26: 27.4 | E26: 0.788236 | F26: 0.253757 | G26: 90.8647 | H26: https://api.worldbank.org/v2/country/FIN/indicator/NY.GDP.PCAP.PP.CD?format=json&mrv=30 | https://api.worldbank.org/v2/country/FIN/indicator/NY.GDP.MKTP.KD.ZG?format=json&mrv=30 | https://api.worldbank.org/v2/country/FIN/indicator/SI.POV.GINI?format=json&mrv=30 | +3 more | I26: Tier 3 | J26: 2024-12-31 | K26: providers=world_bank; fields=gdp_per_capita_ppp, gdp_growth, gini_coefficient, ppp_private_consumption; +2 additional fields
... A37: Costa Rica | B37: 31106.76 | C37: 4.3212 | D37: 45.8 | E37: 328.04659 | F37: 0.139115 | G37: 50.9742 | H37: https://api.worldbank.org/v2/country/CRI/indicator/NY.GDP.PCAP.PP.CD?format=json&mrv=30 | https://api.worldbank.org/v2/country/CRI/indicator/NY.GDP.MKTP.KD.ZG?format=json&mrv=30 | https://api.worldbank.org/v2/country/CRI/indicator/SI.POV.GINI?format=json&mrv=30 | +3 more | I37: Tier 3 | J37: 2024-12-31 | K37: providers=world_bank; fields=gdp_per_capita_ppp, gdp_growth, gini_coefficient, ppp_private_consumption; +2 additional fields
A38: Puerto Rico | B38: 50247.85 | C38: 3.1771 | E38: 0.896932 | H38: https://api.worldbank.org/v2/country/PRI/indicator/NY.GDP.PCAP.PP.CD?format=json&mrv=30 | https://api.worldbank.org/v2/country/PRI/indicator/NY.GDP.MKTP.KD.ZG?format=json&mrv=30 | https://api.worldbank.org/v2/country/PRI/indicator/PA.NUS.PRVT.PP?format=json&mrv=30 | I38: Tier 3 | J38: 2024-12-31 | K38: providers=world_bank; fields=gdp_per_capita_ppp, gdp_growth, ppp_private_consumption
A39: Brazil | B39: 22338.48 | C39: 3.4193 | D39: 51.6 | E39: 2.524497 | F39: 0.154102 | G39: 75.6164 | H39: https://api.worldbank.org/v2/country/BRA/indicator/NY.GDP.PCAP.PP.CD?format=json&mrv=30 | https://api.worldbank.org/v2/country/BRA/indicator/NY.GDP.MKTP.KD.ZG?format=json&mrv=30 | https://api.worldbank.org/v2/country/BRA/indicator/SI.POV.GINI?format=json&mrv=30 | +3 more | I39: Tier 3 | J39: 2024-12-31 | K39: providers=world_bank; fields=gdp_per_capita_ppp, gdp_growth, gini_coefficient, ppp_private_consumption; +2 additional fields
A40: Argentina | B40: 30431.19 | C40: -1.3429 | D40: 42.4 | E40: 42.98624 | F40: 0.099289 | G40: 13.0788 | H40: https://api.worldbank.org/v2/country/ARG/indicator/NY.GDP.PCAP.PP.CD?format=json&mrv=30 | https://api.worldbank.org/v2/country/ARG/indicator/NY.GDP.MKTP.KD.ZG?format=json&mrv=30 | https://api.worldbank.org/v2/country/ARG/indicator/SI.POV.GINI?format=json&mrv=30 | +3 more | I40: Tier 3 | J40: 2024-12-31 | K40: providers=world_bank; fields=gdp_per_capita_ppp, gdp_growth, gini_coefficient, ppp_private_consumption; +2 additional fields
A41: Chile | B41: 36181.16 | C41: 2.6443 | D41: 43 | E41: 464.87603 | F41: 0.177194 | G41: 74.9355 | H41: https://api.worldbank.org/v2/country/CHL/indicator/NY.GDP.PCAP.PP.CD?format=json&mrv=30 | https://api.worldbank.org/v2/country/CHL/indicator/NY.GDP.MKTP.KD.ZG?format=json&mrv=30 | https://api.worldbank.org/v2/country/CHL/indicator/SI.POV.GINI?format=json&mrv=30 | +3 more | I41: Tier 3 | J41: 2024-12-31 | K41: providers=world_bank; fields=gdp_per_capita_ppp, gdp_growth, gini_coefficient, ppp_private_consumption; +2 additional fields
A42: Colombia | B42: 22349.44 | C42: 1.5983 | D42: 53.9 | E42: 1542.1938 | F42: 0.152812 | G42: 39.5117 | H42: https://api.worldbank.org/v2/country/COL/indicator/NY.GDP.PCAP.PP.CD?format=json&mrv=30 | https://api.worldbank.org/v2/country/COL/indicator/NY.GDP.MKTP.KD.ZG?format=json&mrv=30 | https://api.worldbank.org/v2/country/COL/indicator/SI.POV.GINI?format=json&mrv=30 | +3 more | I42: Tier 3 | J42: 2024-12-31 | K42: providers=world_bank; fields=gdp_per_capita_ppp, gdp_growth, gini_coefficient, ppp_private_consumption; +2 additional fields
A43: Peru | B43: 17802.42 | C43: 3.3039 | D43: 40.1 | E43: 1.94918 | F43: 0.159243 | G43: 45.668 | H43: https://api.worldbank.org/v2/country/PER/indicator/NY.GDP.PCAP.PP.CD?format=json&mrv=30 | https://api.worldbank.org/v2/country/PER/indicator/NY.GDP.MKTP.KD.ZG?format=json&mrv=30 | https://api.worldbank.org/v2/country/PER/indicator/SI.POV.GINI?format=json&mrv=30 | +3 more | I43: Tier 3 | J43: 2024-12-31 | K43: providers=world_bank; fields=gdp_per_capita_ppp, gdp_growth, gini_coefficient, ppp_private_consumption; +2 additional fields
A44: Uruguay | B44: 36417.87 | C44: 3.1083 | D44: 40 | E44: 29.298217 | F44: 0.181624 | G44: 31.0608 | H44: https://api.worldbank.org/v2/country/URY/indicator/NY.GDP.PCAP.PP.CD?format=json&mrv=30 | https://api.worldbank.org/v2/country/URY/indicator/NY.GDP.MKTP.KD.ZG?format=json&mrv=30 | https://api.worldbank.org/v2/country/URY/indicator/SI.POV.GINI?format=json&mrv=30 | +3 more | I44: Tier 3 | J44: 2024-12-31 | K44: providers=world_bank; fields=gdp_per_capita_ppp, gdp_growth, gini_coefficient, ppp_private_consumption; +2 additional fields
A45: United Arab Emirates | B45: 79228.74 | C45: 3.9918 | D45: 26.4 | E45: 2.56311 | F45: 0.006475 | G45: 67.9658 | H45: https://api.worldbank.org/v2/country/ARE/indicator/NY.GDP.PCAP.PP.CD?format=json&mrv=30 | https://api.worldbank.org/v2/country/ARE/indicator/NY.GDP.MKTP.KD.ZG?format=json&mrv=30 | https://api.worldbank.org/v2/country/ARE/indicator/SI.POV.GINI?format=json&mrv=30 | +3 more | I45: Tier 3 | J45: 2024-12-31 | K45: providers=world_bank; fields=gdp_per_capita_ppp, gdp_growth, gini_coefficient, ppp_private_consumption; +2 additional fields
A46: Qatar | B46: 126046.35 | C46: 2.3597 | D46: 35.1 | E46: 2.755487 | G46: 118.8652 | H46: https://api.worldbank.org/v2/country/QAT/indicator/NY.GDP.PCAP.PP.CD?format=json&mrv=30 | https://api.worldbank.org/v2/country/QAT/indicator/NY.GDP.MKTP.KD.ZG?format=json&mrv=30 | https://api.worldbank.org/v2/country/QAT/indicator/SI.POV.GINI?format=json&mrv=30 | +2 more | I46: Tier 3 | J46: 2024-12-31 | K46: providers=world_bank; fields=gdp_per_capita_ppp, gdp_growth, gini_coefficient, ppp_private_consumption; +1 additional fields
A47: Saudi Arabia | B47: 71375.37 | C47: 1.9965 | E47: 1.882361 | F47: 0.081847 | G47: 50.1376 | H47: https://api.worldbank.org/v2/country/SAU/indicator/NY.GDP.PCAP.PP.CD?format=json&mrv=30 | https://api.worldbank.org/v2/country/SAU/indicator/NY.GDP.MKTP.KD.ZG?format=json&mrv=30 | https://api.worldbank.org/v2/country/SAU/indicator/PA.NUS.PRVT.PP?format=json&mrv=30 | +2 more | I47: Tier 3 | J47: 2024-12-31 | K47: providers=world_bank; fields=gdp_per_capita_ppp, gdp_growth, ppp_private_consumption, tax_rate_assumption; +1 additional fields
A48: Israel | B48: 57235.78 | C48: 0.872 | D48: 37.9 | E48: 3.607983 | F48: 0.221364 | G48: 69.7497 | H48: https://api.worldbank.org/v2/country/ISR/indicator/NY.GDP.PCAP.PP.CD?format=json&mrv=30 | https://api.worldbank.org/v2/country/ISR/indicator/NY.GDP.MKTP.KD.ZG?format=json&mrv=30 | https://api.worldbank.org/v2/country/ISR/indicator/SI.POV.GINI?format=json&mrv=30 | +3 more | I48: Tier 3 | J48: 2024-12-31 | K48: providers=world_bank; fields=gdp_per_capita_ppp, gdp_growth, gini_coefficient, ppp_private_consumption; +2 additional fields
A49: Oman | B49: 41740.17 | C49: 1.6316 | E49: 0.184982 | G49: 59.7083 | H49: https://api.worldbank.org/v2/country/OMN/indicator/NY.GDP.PCAP.PP.CD?format=json&mrv=30 | https://api.worldbank.org/v2/country/OMN/indicator/NY.GDP.MKTP.KD.ZG?format=json&mrv=30 | https://api.worldbank.org/v2/country/OMN/indicator/PA.NUS.PRVT.PP?format=json&mrv=30 | +1 more | I49: Tier 3 | J49: 2024-12-31 | K49: providers=world_bank; fields=gdp_per_capita_ppp, gdp_growth, ppp_private_consumption, household_debt_proxy
A50: Bahrain | B50: 66941.24 | C50: 2.6038 | E50: 0.188671 | F50: 0.028232 | G50: 70.5501 | H50: https://api.worldbank.org/v2/country/BHR/indicator/NY.GDP.PCAP.PP.CD?format=json&mrv=30 | https://api.worldbank.org/v2/country/BHR/indicator/NY.GDP.MKTP.KD.ZG?format=json&mrv=30 | https://api.worldbank.org/v2/country/BHR/indicator/PA.NUS.PRVT.PP?format=json&mrv=30 | +2 more | I50: Tier 3 | J50: 2024-12-31 | K50: providers=world_bank; fields=gdp_per_capita_ppp, gdp_growth, ppp_private_consumption, tax_rate_assumption; +1 additional fields
...

Sheet City_Inputs
A1: city_id | B1: display_name | C1: country | D1: cohort | E1: city_type | F1: manifest_status | G1: gross_income | H1: rent | I1: utilities | J1: transit_cost | K1: internet_cost | L1: food_cost | M1: di_ppp_raw | N1: housing_burden_raw | O1: household_debt_burden_raw | P1: household_debt_effective_raw | Q1: working_time_pressure_raw | R1: suicide_mental_strain_raw | S1: personal_safety_raw | T1: transit_access_commute_raw | U1: clean_air_raw | V1: water_sanitation_utility_raw | W1: digital_infrastructure_raw | X1: climate_sunlight_livability_raw | Y1: healthcare_quality_raw | Z1: education_quality_raw | AA1: equal_opportunity_raw | AB1: hospitality_belonging_raw | AC1: tolerance_pluralism_raw | AD1: cultural_public_life_raw | AE1: entrepreneurial_dynamism_raw | AF1: innovation_research_intensity_raw | AG1: investment_signal_raw | AH1: administrative_investment_friction_raw | AI1: visitor_flow_context_raw | AJ1: gdp_per_capita_ppp_context | AK1: gdp_growth_context | AL1: gini_coefficient_context | AM1: ppp_private_consumption_context | AN1: tax_rate_context | AO1: household_debt_proxy_context | AP1: pressure_source_url | AQ1: pressure_source_tier | AR1: pressure_source_date | AS1: pressure_notes | AT1: viability_source_url | AU1: viability_source_tier | AV1: viability_source_date | AW1: viability_notes | AX1: capability_source_url | AY1: capability_source_tier | AZ1: capability_source_date | BA1: capability_notes | BB1: community_source_url | BC1: community_source_tier | BD1: community_source_date | BE1: community_notes | BF1: creative_source_url | BG1: creative_source_tier | BH1: creative_source_date | BI1: creative_notes | BJ1: birth_rate_optimism_raw
A2: th-bangkok | B2: Bangkok | C2: Thailand | D2: Southeast Asia | E2: primary | F2: locked | G2: 1996.67 | H2: 399.33 | I2: 99.83 | J2: 79.87 | K2: 29.95 | L2: 439.27 | N2: 19.9998 | O2: 115.1054 | P2: =IF($O2<>"",$O2,$AO2) | Q2: 42.53 | R2: 16.59 | S2: 2.2 | U2: 25 | V2: 93 | W2: 15.75 | X2: 72 | Y2: 82 | Z2: 49.08 | AA2: 33.5 | AB2: 50.38 | AC2: 42 | AD2: 556.96 | AE2: 1.54 | AF2: 1.16 | AG2: 2.72 | AH2: 2.34 | AJ2: =IFERROR(INDEX(Country_Context!$B$2:$B$87,MATCH($C2,Country_Context!$A$2:$A$87,0)),"") | AK2: =IFERROR(INDEX(Country_Context!$C$2:$C$87,MATCH($C2,Country_Context!$A$2:$A$87,0)),"") | AL2: =IFERROR(INDEX(Country_Context!$D$2:$D$87,MATCH($C2,Country_Context!$A$2:$A$87,0)),"") | AM2: =IFERROR(INDEX(Country_Context!$E$2:$E$87,MATCH($C2,Country_Context!$A$2:$A$87,0)),"") | AN2: =IFERROR(INDEX(Country_Context!$F$2:$F$87,MATCH($C2,Country_Context!$A$2:$A$87,0)),"") | AO2: =IFERROR(INDEX(Country_Context!$G$2:$G$87,MATCH($C2,Country_Context!$A$2:$A$87,0)),"") | AP2: https://api.worldbank.org/v2/country/THA/indicator/NY.GNP.PCAP.PP.CD?format=json&mrv=10 | https://data.worldbank.org/indicator/NY.GNP.PCAP.PP.CD | https://ilostat.ilo.org/data/indicator/?id=HOW_TEMP_SEX_ECO_NB_A&ref_area=THA | +4 more | AQ2: Tier 3, Tier 4 | AR2: 2024-12-31 | AS2: providers=world_bank_col_estimate, derived, ilo_ilostat, who_gho; fields=gross_income, rent, utilities, transit_cost; +9 additional fields | AT2: https://api.worldbank.org/v2/country/THA/indicator/VC.IHR.PSRC.P5?format=json&mrv=10 | https://www.pcd.go.th/ | https://washdata.org | +2 more | AU2: Tier 2, Tier 3 | AV2: 2024-12-31 | AW2: providers=world_bank, thai_gov_pcd_rsc, who_unicef_jmp; fields=personal_safety_raw, clean_air_raw, water_sanitation_utility_raw, digital_infrastructure_raw; +1 additional fields | AX2: https://www.who.int/data/gho/data/indicators/indicator-details/GHO/UHC_INDEX_REPORTED | https://api.worldbank.org/v2/country/THA/indicator/SE.TER.ENRR?format=json&mrv=10 | https://api.worldbank.org/v2/country/THA/indicator/SI.POV.GINI?format=json&mrv=10 | +1 more | AY2: Tier 3 | AZ2: 2025-12-31 | BA2: providers=who_gho, world_bank; fields=healthcare_quality_raw, education_quality_raw, equal_opportunity_raw, gini_coefficient | BB2: https://api.worldbank.org/v2/country/THA/indicator/SM.POP.NETM?format=json&mrv=10 | https://api.worldbank.org/v2/country/THA/indicator/SG.GEN.PARL.ZS?format=json | https://api.worldbank.org/v2/country/THA/indicator/ST.INT.ARVL?format=json&mrv=10 | +1 more | BC2: Tier 3 | BD2: 2025-12-31 | BE2: providers=world_bank; fields=hospitality_belonging_raw, tolerance_pluralism_raw, cultural_public_life_raw, birth_rate_optimism_raw | BF2: https://api.worldbank.org/v2/country/THA/indicator/IC.BUS.NDNS.ZS?format=json&mrv=10 | https://api.worldbank.org/v2/country/THA/indicator/GB.XPD.RSDV.GD.ZS?format=json&mrv=10 | https://api.worldbank.org/v2/country/THA/indicator/BX.KLT.DINV.WD.GD.ZS?format=json&mrv=10 | +3 more | BG2: Tier 3 | BH2: 2024-12-31 | BI2: providers=world_bank; fields=entrepreneurial_dynamism_raw, innovation_research_intensity_raw, investment_signal_raw, administrative_investment_friction_raw; +2 additional fields | BJ2: 1.08
A3: sg-singapore | B3: Singapore | C3: Singapore | D3: Southeast Asia | E3: primary | F3: locked | G3: 10515.83 | H3: 2839.27 | I3: 709.82 | J3: 567.85 | K3: 212.95 | L3: 3123.2 | N3: 27 | O3: 129.1908 | P3: =IF($O3<>"",$O3,$AO3) | Q3: 42.6 | R3: 8.1 | S3: 0.07 | V3: 100 | W3: 27.43 | X3: 62 | Y3: 88 | Z3: 97.29 | AB3: 52.8 | AC3: 29.29 | AD3: 454.21 | AE3: 11.32 | AF3: 2.16 | AG3: 27.76 | AH3: 0.19 | AJ3: =IFERROR(INDEX(Country_Context!$B$2:$B$87,MATCH($C3,Country_Context!$A$2:$A$87,0)),"") | AK3: =IFERROR(INDEX(Country_Context!$C$2:$C$87,MATCH($C3,Country_Context!$A$2:$A$87,0)),"") | AL3: =IFERROR(INDEX(Country_Context!$D$2:$D$87,MATCH($C3,Country_Context!$A$2:$A$87,0)),"") | AM3: =IFERROR(INDEX(Country_Context!$E$2:$E$87,MATCH($C3,Country_Context!$A$2:$A$87,0)),"") | AN3: =IFERROR(INDEX(Country_Context!$F$2:$F$87,MATCH($C3,Country_Context!$A$2:$A$87,0)),"") | AO3: =IFERROR(INDEX(Country_Context!$G$2:$G$87,MATCH($C3,Country_Context!$A$2:$A$87,0)),"") | AP3: https://api.worldbank.org/v2/country/SGP/indicator/NY.GNP.PCAP.PP.CD?format=json&mrv=10 | https://data.worldbank.org/indicator/NY.GNP.PCAP.PP.CD | https://ilostat.ilo.org/data/indicator/?id=HOW_TEMP_SEX_ECO_NB_A&ref_area=SGP | +4 more | AQ3: Tier 3, Tier 4 | AR3: 2024-12-31 | AS3: providers=world_bank_col_estimate, derived, ilo_ilostat, who_gho; fields=gross_income, rent, utilities, transit_cost; +9 additional fields | AT3: https://api.worldbank.org/v2/country/SGP/indicator/VC.IHR.PSRC.P5?format=json&mrv=10 | https://api.worldbank.org/v2/country/SGP/indicator/SH.H2O.SMDW.ZS?format=json&mrv=10 | https://api.worldbank.org/v2/country/SGP/indicator/IT.NET.BBND.P2?format=json&mrv=10 | +1 more | AU3: Tier 3 | AV3: 2024-12-31 | AW3: providers=world_bank, wmo_natl_met; fields=personal_safety_raw, water_sanitation_utility_raw, digital_infrastructure_raw, climate_sunlight_livability_raw | AX3: https://www.who.int/data/gho/data/indicators/indicator-details/GHO/UHC_INDEX_REPORTED | https://api.worldbank.org/v2/country/SGP/indicator/SE.TER.ENRR?format=json&mrv=10 | AY3: Tier 3 | AZ3: 2023-12-31 | BA3: providers=who_gho, world_bank; fields=healthcare_quality_raw, education_quality_raw | BB3: https://api.worldbank.org/v2/country/SGP/indicator/SM.POP.NETM?format=json&mrv=10 | https://api.worldbank.org/v2/country/SGP/indicator/SG.GEN.PARL.ZS?format=json&mrv=10 | https://api.worldbank.org/v2/country/SGP/indicator/ST.INT.ARVL?format=json&mrv=10 | +1 more | BC3: Tier 3 | BD3: 2025-12-31 | BE3: providers=world_bank; fields=hospitality_belonging_raw, tolerance_pluralism_raw, cultural_public_life_raw, birth_rate_optimism_raw | BF3: https://api.worldbank.org/v2/country/SGP/indicator/IC.BUS.NDNS.ZS?format=json&mrv=10 | https://api.worldbank.org/v2/country/SGP/indicator/GB.XPD.RSDV.GD.ZS?format=json&mrv=10 | https://api.worldbank.org/v2/country/SGP/indicator/BX.KLT.DINV.WD.GD.ZS?format=json&mrv=10 | +3 more | BG3: Tier 3 | BH3: 2024-12-31 | BI3: providers=world_bank; fields=entrepreneurial_dynamism_raw, innovation_research_intensity_raw, investment_signal_raw, administrative_investment_friction_raw; +2 additional fields | BJ3: 0.97
A4: my-kuala-lumpur | B4: Kuala Lumpur | C4: Malaysia | D4: Southeast Asia | E4: primary | F4: locked | G4: 3120.83 | H4: 624.17 | I4: 156.04 | J4: 124.83 | K4: 46.81 | L4: 686.58 | N4: 20.0001 | O4: 116.0773 | P4: =IF($O4<>"",$O4,$AO4) | Q4: 44.7 | R4: 5.65 | S4: 0.73 | V4: 94.7 | W4: 13.03 | X4: 56 | Y4: 80 | Z4: 38.5 | AA4: 40.7 | AB4: 54.69 | AC4: 13.51 | AD4: 121.86 | AE4: 2.19 | AF4: 0.95 | AG4: 3.69 | AH4: 1.84 | AJ4: =IFERROR(INDEX(Country_Context!$B$2:$B$87,MATCH($C4,Country_Context!$A$2:$A$87,0)),"") | AK4: =IFERROR(INDEX(Country_Context!$C$2:$C$87,MATCH($C4,Country_Context!$A$2:$A$87,0)),"") | AL4: =IFERROR(INDEX(Country_Context!$D$2:$D$87,MATCH($C4,Country_Context!$A$2:$A$87,0)),"") | AM4: =IFERROR(INDEX(Country_Context!$E$2:$E$87,MATCH($C4,Country_Context!$A$2:$A$87,0)),"") | AN4: =IFERROR(INDEX(Country_Context!$F$2:$F$87,MATCH($C4,Country_Context!$A$2:$A$87,0)),"") | AO4: =IFERROR(INDEX(Country_Context!$G$2:$G$87,MATCH($C4,Country_Context!$A$2:$A$87,0)),"") | AP4: https://api.worldbank.org/v2/country/MYS/indicator/NY.GNP.PCAP.PP.CD?format=json&mrv=10 | https://data.worldbank.org/indicator/NY.GNP.PCAP.PP.CD | https://ilostat.ilo.org/data/indicator/?id=HOW_TEMP_SEX_ECO_NB_A&ref_area=MYS | +4 more | AQ4: Tier 3, Tier 4 | AR4: 2024-12-31 | AS4: providers=world_bank_col_estimate, derived, ilo_ilostat, who_gho; fields=gross_income, rent, utilities, transit_cost; +9 additional fields | AT4: https://api.worldbank.org/v2/country/MYS/indicator/VC.IHR.PSRC.P5?format=json&mrv=10 | https://api.worldbank.org/v2/country/MYS/indicator/SH.H2O.SMDW.ZS?format=json&mrv=10 | https://api.worldbank.org/v2/country/MYS/indicator/IT.NET.BBND.P2?format=json&mrv=10 | +1 more | AU4: Tier 3 | AV4: 2024-12-31 | AW4: providers=world_bank, wmo_natl_met; fields=personal_safety_raw, water_sanitation_utility_raw, digital_infrastructure_raw, climate_sunlight_livability_raw | AX4: https://www.who.int/data/gho/data/indicators/indicator-details/GHO/UHC_INDEX_REPORTED | https://api.worldbank.org/v2/country/MYS/indicator/SE.TER.ENRR?format=json&mrv=10 | https://api.worldbank.org/v2/country/MYS/indicator/SI.POV.GINI?format=json&mrv=10 | +1 more | AY4: Tier 3 | AZ4: 2024-12-31 | BA4: providers=who_gho, world_bank; fields=healthcare_quality_raw, education_quality_raw, equal_opportunity_raw, gini_coefficient | BB4: https://api.worldbank.org/v2/country/MYS/indicator/SM.POP.NETM?format=json&mrv=10 | https://api.worldbank.org/v2/country/MYS/indicator/SG.GEN.PARL.ZS?format=json&mrv=10 | https://api.worldbank.org/v2/country/MYS/indicator/ST.INT.ARVL?format=json&mrv=10 | +1 more | BC4: Tier 3 | BD4: 2025-12-31 | BE4: providers=world_bank; fields=hospitality_belonging_raw, tolerance_pluralism_raw, cultural_public_life_raw, birth_rate_optimism_raw | BF4: https://api.worldbank.org/v2/country/MYS/indicator/IC.BUS.NDNS.ZS?format=json&mrv=10 | https://api.worldbank.org/v2/country/MYS/indicator/GB.XPD.RSDV.GD.ZS?format=json&mrv=10 | https://api.worldbank.org/v2/country/MYS/indicator/BX.KLT.DINV.WD.GD.ZS?format=json&mrv=10 | +3 more | BG4: Tier 3 | BH4: 2024-12-31 | BI4: providers=world_bank; fields=entrepreneurial_dynamism_raw, innovation_research_intensity_raw, investment_signal_raw, administrative_investment_friction_raw; +2 additional fields | BJ4: 1.6
A5: id-jakarta | B5: Jakarta | C5: Indonesia | D5: Southeast Asia | E5: primary | F5: provisional | G5: 1334.17 | H5: 266.83 | I5: 66.71 | J5: 53.37 | K5: 20.01 | L5: 293.52 | N5: 19.9997 | O5: 31.7861 | P5: =IF($O5<>"",$O5,$AO5) | Q5: 38.36 | R5: 1.2 | S5: 0.3 | V5: 30.46 | W5: 4.82 | X5: 54 | Y5: 67 | Z5: 44.88 | AA5: 34.9 | AB5: 49.86 | AC5: 21.03 | AD5: 14.3 | AE5: 0.33 | AF5: 0.28 | AG5: 1.74 | AH5: 2.2 | AJ5: =IFERROR(INDEX(Country_Context!$B$2:$B$87,MATCH($C5,Country_Context!$A$2:$A$87,0)),"") | AK5: =IFERROR(INDEX(Country_Context!$C$2:$C$87,MATCH($C5,Country_Context!$A$2:$A$87,0)),"") | AL5: =IFERROR(INDEX(Country_Context!$D$2:$D$87,MATCH($C5,Country_Context!$A$2:$A$87,0)),"") | AM5: =IFERROR(INDEX(Country_Context!$E$2:$E$87,MATCH($C5,Country_Context!$A$2:$A$87,0)),"") | AN5: =IFERROR(INDEX(Country_Context!$F$2:$F$87,MATCH($C5,Country_Context!$A$2:$A$87,0)),"") | AO5: =IFERROR(INDEX(Country_Context!$G$2:$G$87,MATCH($C5,Country_Context!$A$2:$A$87,0)),"") | AP5: https://api.worldbank.org/v2/country/IDN/indicator/NY.GNP.PCAP.PP.CD?format=json&mrv=10 | https://data.worldbank.org/indicator/NY.GNP.PCAP.PP.CD | https://ilostat.ilo.org/data/indicator/?id=HOW_TEMP_SEX_ECO_NB_A&ref_area=IDN | +4 more | AQ5: Tier 3, Tier 4 | AR5: 2024-12-31 | AS5: providers=world_bank_col_estimate, derived, ilo_ilostat, who_gho; fields=gross_income, rent, utilities, transit_cost; +9 additional fields | AT5: https://api.worldbank.org/v2/country/IDN/indicator/VC.IHR.PSRC.P5?format=json&mrv=10 | https://api.worldbank.org/v2/country/IDN/indicator/SH.H2O.SMDW.ZS?format=json&mrv=10 | https://api.worldbank.org/v2/country/IDN/indicator/IT.NET.BBND.P2?format=json&mrv=10 | +1 more | AU5: Tier 3 | AV5: 2024-12-31 | AW5: providers=world_bank, wmo_natl_met; fields=personal_safety_raw, water_sanitation_utility_raw, digital_infrastructure_raw, climate_sunlight_livability_raw | AX5: https://www.who.int/data/gho/data/indicators/indicator-details/GHO/UHC_INDEX_REPORTED | https://api.worldbank.org/v2/country/IDN/indicator/SE.TER.ENRR?format=json&mrv=10 | https://api.worldbank.org/v2/country/IDN/indicator/SI.POV.GINI?format=json&mrv=10 | +1 more | AY5: Tier 3 | AZ5: 2024-12-31 | BA5: providers=who_gho, world_bank; fields=healthcare_quality_raw, education_quality_raw, equal_opportunity_raw, gini_coefficient | BB5: https://api.worldbank.org/v2/country/IDN/indicator/SM.POP.NETM?format=json&mrv=10 | https://api.worldbank.org/v2/country/IDN/indicator/SG.GEN.PARL.ZS?format=json&mrv=10 | https://api.worldbank.org/v2/country/IDN/indicator/ST.INT.ARVL?format=json&mrv=10 | BC5: Tier 3 | BD5: 2025-12-31 | BE5: providers=world_bank; fields=hospitality_belonging_raw, tolerance_pluralism_raw, cultural_public_life_raw | BF5: https://api.worldbank.org/v2/country/IDN/indicator/IC.BUS.NDNS.ZS?format=json&mrv=10 | https://api.worldbank.org/v2/country/IDN/indicator/GB.XPD.RSDV.GD.ZS?format=json&mrv=10 | https://api.worldbank.org/v2/country/IDN/indicator/BX.KLT.DINV.WD.GD.ZS?format=json&mrv=10 | +3 more | BG5: Tier 3 | BH5: 2024-12-31 | BI5: providers=world_bank; fields=entrepreneurial_dynamism_raw, innovation_research_intensity_raw, investment_signal_raw, administrative_investment_friction_raw; +2 additional fields
A6: ph-makati | B6: Makati | C6: Philippines | D6: Southeast Asia | E6: primary | F6: provisional | G6: 1110.83 | H6: 222.17 | I6: 55.54 | J6: 44.43 | K6: 16.66 | L6: 244.38 | N6: 20.0004 | O6: 49.8137 | P6: =IF($O6<>"",$O6,$AO6) | Q6: 39.99 | R6: 3.49 | S6: 4.35 | V6: 48.48 | W6: 6.54 | Y6: 69 | Z6: 47.41 | AA6: 39.3 | AB6: 48.71 | AC6: 27.33 | AD6: 12.8 | AE6: 0.34 | AF6: 0.32 | AG6: 2.04 | AH6: 2.34 | AJ6: =IFERROR(INDEX(Country_Context!$B$2:$B$87,MATCH($C6,Country_Context!$A$2:$A$87,0)),"") | AK6: =IFERROR(INDEX(Country_Context!$C$2:$C$87,MATCH($C6,Country_Context!$A$2:$A$87,0)),"") | AL6: =IFERROR(INDEX(Country_Context!$D$2:$D$87,MATCH($C6,Country_Context!$A$2:$A$87,0)),"") | AM6: =IFERROR(INDEX(Country_Context!$E$2:$E$87,MATCH($C6,Country_Context!$A$2:$A$87,0)),"") | AN6: =IFERROR(INDEX(Country_Context!$F$2:$F$87,MATCH($C6,Country_Context!$A$2:$A$87,0)),"") | AO6: =IFERROR(INDEX(Country_Context!$G$2:$G$87,MATCH($C6,Country_Context!$A$2:$A$87,0)),"") | AP6: https://api.worldbank.org/v2/country/PHL/indicator/NY.GNP.PCAP.PP.CD?format=json&mrv=10 | https://data.worldbank.org/indicator/NY.GNP.PCAP.PP.CD | https://ilostat.ilo.org/data/indicator/?id=HOW_TEMP_SEX_ECO_NB_A&ref_area=PHL | +4 more | AQ6: Tier 3, Tier 4 | AR6: 2024-12-31 | AS6: providers=world_bank_col_estimate, derived, ilo_ilostat, who_gho; fields=gross_income, rent, utilities, transit_cost; +9 additional fields | AT6: https://api.worldbank.org/v2/country/PHL/indicator/VC.IHR.PSRC.P5?format=json&mrv=10 | https://api.worldbank.org/v2/country/PHL/indicator/SH.H2O.SMDW.ZS?format=json&mrv=10 | https://api.worldbank.org/v2/country/PHL/indicator/IT.NET.BBND.P2?format=json&mrv=10 | AU6: Tier 3 | AV6: 2024-12-31 | AW6: providers=world_bank; fields=personal_safety_raw, water_sanitation_utility_raw, digital_infrastructure_raw | AX6: https://www.who.int/data/gho/data/indicators/indicator-details/GHO/UHC_INDEX_REPORTED | https://api.worldbank.org/v2/country/PHL/indicator/SE.TER.ENRR?format=json&mrv=10 | https://api.worldbank.org/v2/country/PHL/indicator/SI.POV.GINI?format=json&mrv=10 | +1 more | AY6: Tier 3 | AZ6: 2024-12-31 | BA6: providers=who_gho, world_bank; fields=healthcare_quality_raw, education_quality_raw, equal_opportunity_raw, gini_coefficient | BB6: https://api.worldbank.org/v2/country/PHL/indicator/SM.POP.NETM?format=json&mrv=10 | https://api.worldbank.org/v2/country/PHL/indicator/SG.GEN.PARL.ZS?format=json&mrv=10 | https://api.worldbank.org/v2/country/PHL/indicator/ST.INT.ARVL?format=json&mrv=10 | BC6: Tier 3 | BD6: 2025-12-31 | BE6: providers=world_bank; fields=hospitality_belonging_raw, tolerance_pluralism_raw, cultural_public_life_raw | BF6: https://api.worldbank.org/v2/country/PHL/indicator/IC.BUS.NDNS.ZS?format=json&mrv=10 | https://api.worldbank.org/v2/country/PHL/indicator/GB.XPD.RSDV.GD.ZS?format=json&mrv=10 | https://api.worldbank.org/v2/country/PHL/indicator/BX.KLT.DINV.WD.GD.ZS?format=json&mrv=10 | +3 more | BG6: Tier 3 | BH6: 2024-12-31 | BI6: providers=world_bank; fields=entrepreneurial_dynamism_raw, innovation_research_intensity_raw, investment_signal_raw, administrative_investment_friction_raw; +2 additional fields
A7: my-george-town | B7: George Town | C7: Malaysia | D7: Southeast Asia | E7: secondary | F7: locked | G7: 3120.83 | H7: 499.33 | I7: 124.83 | J7: 99.87 | K7: 37.45 | L7: 549.27 | N7: 15.9999 | O7: 116.0773 | P7: =IF($O7<>"",$O7,$AO7) | Q7: 44.7 | R7: 5.65 | S7: 0.73 | V7: 94.7 | W7: 13.03 | Y7: 80 | Z7: 38.5 | AA7: 40.7 | AB7: 54.69 | AC7: 13.51 | AD7: 121.86 | AE7: 2.19 | AF7: 0.95 | AG7: 3.69 | AH7: 1.84 | AJ7: =IFERROR(INDEX(Country_Context!$B$2:$B$87,MATCH($C7,Country_Context!$A$2:$A$87,0)),"") | AK7: =IFERROR(INDEX(Country_Context!$C$2:$C$87,MATCH($C7,Country_Context!$A$2:$A$87,0)),"") | AL7: =IFERROR(INDEX(Country_Context!$D$2:$D$87,MATCH($C7,Country_Context!$A$2:$A$87,0)),"") | AM7: =IFERROR(INDEX(Country_Context!$E$2:$E$87,MATCH($C7,Country_Context!$A$2:$A$87,0)),"") | AN7: =IFERROR(INDEX(Country_Context!$F$2:$F$87,MATCH($C7,Country_Context!$A$2:$A$87,0)),"") | AO7: =IFERROR(INDEX(Country_Context!$G$2:$G$87,MATCH($C7,Country_Context!$A$2:$A$87,0)),"") | AP7: https://api.worldbank.org/v2/country/MYS/indicator/NY.GNP.PCAP.PP.CD?format=json&mrv=10 | https://data.worldbank.org/indicator/NY.GNP.PCAP.PP.CD | https://ilostat.ilo.org/data/indicator/?id=HOW_TEMP_SEX_ECO_NB_A&ref_area=MYS | +4 more | AQ7: Tier 3, Tier 4 | AR7: 2024-12-31 | AS7: providers=world_bank_col_estimate, derived, ilo_ilostat, who_gho; fields=gross_income, rent, utilities, transit_cost; +9 additional fields | AT7: https://api.worldbank.org/v2/country/MYS/indicator/VC.IHR.PSRC.P5?format=json&mrv=10 | https://api.worldbank.org/v2/country/MYS/indicator/SH.H2O.SMDW.ZS?format=json&mrv=10 | https://api.worldbank.org/v2/country/MYS/indicator/IT.NET.BBND.P2?format=json&mrv=10 | AU7: Tier 3 | AV7: 2024-12-31 | AW7: providers=world_bank; fields=personal_safety_raw, water_sanitation_utility_raw, digital_infrastructure_raw | AX7: https://www.who.int/data/gho/data/indicators/indicator-details/GHO/UHC_INDEX_REPORTED | https://api.worldbank.org/v2/country/MYS/indicator/SE.TER.ENRR?format=json&mrv=10 | https://api.worldbank.org/v2/country/MYS/indicator/SI.POV.GINI?format=json&mrv=10 | +1 more | AY7: Tier 3 | AZ7: 2024-12-31 | BA7: providers=who_gho, world_bank; fields=healthcare_quality_raw, education_quality_raw, equal_opportunity_raw, gini_coefficient | BB7: https://api.worldbank.org/v2/country/MYS/indicator/SM.POP.NETM?format=json&mrv=10 | https://api.worldbank.org/v2/country/MYS/indicator/SG.GEN.PARL.ZS?format=json&mrv=10 | https://api.worldbank.org/v2/country/MYS/indicator/ST.INT.ARVL?format=json&mrv=10 | +1 more | BC7: Tier 3 | BD7: 2025-12-31 | BE7: providers=world_bank; fields=hospitality_belonging_raw, tolerance_pluralism_raw, cultural_public_life_raw, birth_rate_optimism_raw | BF7: https://api.worldbank.org/v2/country/MYS/indicator/IC.BUS.NDNS.ZS?format=json&mrv=10 | https://api.worldbank.org/v2/country/MYS/indicator/GB.XPD.RSDV.GD.ZS?format=json&mrv=10 | https://api.worldbank.org/v2/country/MYS/indicator/BX.KLT.DINV.WD.GD.ZS?format=json&mrv=10 | +3 more | BG7: Tier 3 | BH7: 2024-12-31 | BI7: providers=world_bank; fields=entrepreneurial_dynamism_raw, innovation_research_intensity_raw, investment_signal_raw, administrative_investment_friction_raw; +2 additional fields | BJ7: 1.6
A8: th-phuket | B8: Phuket | C8: Thailand | D8: Southeast Asia | E8: secondary | F8: locked | G8: 1996.67 | H8: 359.4 | I8: 89.85 | J8: 71.88 | K8: 26.96 | L8: 395.34 | N8: 18 | O8: 115.1054 | P8: =IF($O8<>"",$O8,$AO8) | Q8: 42.53 | R8: 16.59 | U8: 18 | V8: 90 | W8: 15.75 | X8: 60 | Y8: 82 | Z8: 49.08 | AA8: 33.5 | AB8: 50.38 | AC8: 19.4 | AD8: 556.96 | AE8: 1.54 | AF8: 1.16 | AG8: 2.72 | AH8: 2.34 | AJ8: =IFERROR(INDEX(Country_Context!$B$2:$B$87,MATCH($C8,Country_Context!$A$2:$A$87,0)),"") | AK8: =IFERROR(INDEX(Country_Context!$C$2:$C$87,MATCH($C8,Country_Context!$A$2:$A$87,0)),"") | AL8: =IFERROR(INDEX(Country_Context!$D$2:$D$87,MATCH($C8,Country_Context!$A$2:$A$87,0)),"") | AM8: =IFERROR(INDEX(Country_Context!$E$2:$E$87,MATCH($C8,Country_Context!$A$2:$A$87,0)),"") | AN8: =IFERROR(INDEX(Country_Context!$F$2:$F$87,MATCH($C8,Country_Context!$A$2:$A$87,0)),"") | AO8: =IFERROR(INDEX(Country_Context!$G$2:$G$87,MATCH($C8,Country_Context!$A$2:$A$87,0)),"") | AP8: https://api.worldbank.org/v2/country/THA/indicator/NY.GNP.PCAP.PP.CD?format=json&mrv=10 | https://data.worldbank.org/indicator/NY.GNP.PCAP.PP.CD | https://ilostat.ilo.org/data/indicator/?id=HOW_TEMP_SEX_ECO_NB_A&ref_area=THA | +4 more | AQ8: Tier 3, Tier 4 | AR8: 2024-12-31 | AS8: providers=world_bank_col_estimate, derived, ilo_ilostat, who_gho; fields=gross_income, rent, utilities, transit_cost; +9 additional fields | AT8: https://www.pcd.go.th/ | https://www.pwa.co.th/ | https://api.worldbank.org/v2/country/THA/indicator/IT.NET.BBND.P2?format=json&mrv=10 | +1 more | AU8: Tier 2, Tier 3 | AV8: 2024-12-31 | AW8: providers=thai_gov_pcd_rsc, world_bank, wmo_natl_met; fields=clean_air_raw, water_sanitation_utility_raw, digital_infrastructure_raw, climate_sunlight_livability_raw | AX8: https://www.who.int/data/gho/data/indicators/indicator-details/GHO/UHC_INDEX_REPORTED | https://api.worldbank.org/v2/country/THA/indicator/SE.TER.ENRR?format=json&mrv=10 | https://api.worldbank.org/v2/country/THA/indicator/SI.POV.GINI?format=json&mrv=10 | +1 more | AY8: Tier 3 | AZ8: 2025-12-31 | BA8: providers=who_gho, world_bank; fields=healthcare_quality_raw, education_quality_raw, equal_opportunity_raw, gini_coefficient | BB8: https://api.worldbank.org/v2/country/THA/indicator/SM.POP.NETM?format=json&mrv=10 | https://api.worldbank.org/v2/country/THA/indicator/SG.GEN.PARL.ZS?format=json&mrv=10 | https://api.worldbank.org/v2/country/THA/indicator/ST.INT.ARVL?format=json&mrv=10 | +1 more | BC8: Tier 3 | BD8: 2025-12-31 | BE8: providers=world_bank; fields=hospitality_belonging_raw, tolerance_pluralism_raw, cultural_public_life_raw, birth_rate_optimism_raw | BF8: https://api.worldbank.org/v2/country/THA/indicator/IC.BUS.NDNS.ZS?format=json&mrv=10 | https://api.worldbank.org/v2/country/THA/indicator/GB.XPD.RSDV.GD.ZS?format=json&mrv=10 | https://api.worldbank.org/v2/country/THA/indicator/BX.KLT.DINV.WD.GD.ZS?format=json&mrv=10 | +3 more | BG8: Tier 3 | BH8: 2024-12-31 | BI8: providers=world_bank; fields=entrepreneurial_dynamism_raw, innovation_research_intensity_raw, investment_signal_raw, administrative_investment_friction_raw; +2 additional fields | BJ8: 1.08
A9: th-chiang-mai | B9: Chiang Mai | C9: Thailand | D9: Southeast Asia | E9: secondary | F9: locked | G9: 1996.67 | H9: 259.57 | I9: 64.89 | J9: 51.91 | K9: 19.47 | L9: 285.52 | N9: 13.0001 | O9: 115.1054 | P9: =IF($O9<>"",$O9,$AO9) | Q9: 42.53 | R9: 16.59 | U9: 35 | V9: 95 | W9: 15.75 | X9: 64 | Y9: 82 | Z9: 49.08 | AA9: 33.5 | AB9: 50.38 | AC9: 19.4 | AD9: 556.96 | AE9: 1.54 | AF9: 1.16 | AG9: 2.72 | AH9: 2.34 | AJ9: =IFERROR(INDEX(Country_Context!$B$2:$B$87,MATCH($C9,Country_Context!$A$2:$A$87,0)),"") | AK9: =IFERROR(INDEX(Country_Context!$C$2:$C$87,MATCH($C9,Country_Context!$A$2:$A$87,0)),"") | AL9: =IFERROR(INDEX(Country_Context!$D$2:$D$87,MATCH($C9,Country_Context!$A$2:$A$87,0)),"") | AM9: =IFERROR(INDEX(Country_Context!$E$2:$E$87,MATCH($C9,Country_Context!$A$2:$A$87,0)),"") | AN9: =IFERROR(INDEX(Country_Context!$F$2:$F$87,MATCH($C9,Country_Context!$A$2:$A$87,0)),"") | AO9: =IFERROR(INDEX(Country_Context!$G$2:$G$87,MATCH($C9,Country_Context!$A$2:$A$87,0)),"") | AP9: https://api.worldbank.org/v2/country/THA/indicator/NY.GNP.PCAP.PP.CD?format=json&mrv=10 | https://data.worldbank.org/indicator/NY.GNP.PCAP.PP.CD | https://ilostat.ilo.org/data/indicator/?id=HOW_TEMP_SEX_ECO_NB_A&ref_area=THA | +4 more | AQ9: Tier 3, Tier 4 | AR9: 2024-12-31 | AS9: providers=world_bank_col_estimate, derived, ilo_ilostat, who_gho; fields=gross_income, rent, utilities, transit_cost; +9 additional fields | AT9: https://www.pcd.go.th/ | https://www.pwa.co.th/ | https://api.worldbank.org/v2/country/THA/indicator/IT.NET.BBND.P2?format=json&mrv=10 | +1 more | AU9: Tier 2, Tier 3 | AV9: 2024-12-31 | AW9: providers=thai_gov_pcd_rsc, world_bank, wmo_natl_met; fields=clean_air_raw, water_sanitation_utility_raw, digital_infrastructure_raw, climate_sunlight_livability_raw | AX9: https://www.who.int/data/gho/data/indicators/indicator-details/GHO/UHC_INDEX_REPORTED | https://api.worldbank.org/v2/country/THA/indicator/SE.TER.ENRR?format=json&mrv=10 | https://api.worldbank.org/v2/country/THA/indicator/SI.POV.GINI?format=json&mrv=10 | +1 more | AY9: Tier 3 | AZ9: 2025-12-31 | BA9: providers=who_gho, world_bank; fields=healthcare_quality_raw, education_quality_raw, equal_opportunity_raw, gini_coefficient | BB9: https://api.worldbank.org/v2/country/THA/indicator/SM.POP.NETM?format=json&mrv=10 | https://api.worldbank.org/v2/country/THA/indicator/SG.GEN.PARL.ZS?format=json&mrv=10 | https://api.worldbank.org/v2/country/THA/indicator/ST.INT.ARVL?format=json&mrv=10 | +1 more | BC9: Tier 3 | BD9: 2025-12-31 | BE9: providers=world_bank; fields=hospitality_belonging_raw, tolerance_pluralism_raw, cultural_public_life_raw, birth_rate_optimism_raw | BF9: https://api.worldbank.org/v2/country/THA/indicator/IC.BUS.NDNS.ZS?format=json&mrv=10 | https://api.worldbank.org/v2/country/THA/indicator/GB.XPD.RSDV.GD.ZS?format=json&mrv=10 | https://api.worldbank.org/v2/country/THA/indicator/BX.KLT.DINV.WD.GD.ZS?format=json&mrv=10 | +3 more | BG9: Tier 3 | BH9: 2024-12-31 | BI9: providers=world_bank; fields=entrepreneurial_dynamism_raw, innovation_research_intensity_raw, investment_signal_raw, administrative_investment_friction_raw; +2 additional fields | BJ9: 1.08
