Workbook

Sheet Google_Sheets_Guide
A1: SLIC Google Sheets Template
A2: Import this workbook into Google Sheets to collect trusted source inputs, inspect formulas, and rerank transparently.
A3: Current verified-source completion | B3: country values=359/378, city values=8/2652
A4: What to edit | B4: Country_Context and City_Inputs
A5: What not to overwrite | B5: Keep formulas intact in Norm_Stats, Scores, and Leaderboard so the board recalculates correctly.
A6: Trusted source policy | B6: Every filled value should keep a visible source URL, source tier, source date, and note trail.
A7: Provider registry | B7: Use Providers_Registry as the starter reference for approved source families and tiers.
A8: Raw audit tabs | B8: Country_Source_Rows and City_Source_Rows mirror the verified-source CSV pack so the collection workflow stays auditable.
A9: Source guide tabs | B9: Field_Source_Guide sets the preferred evidence for each city metric, and City_Source_Playbook adds curated city-specific starting points such as Milan and Bologna.
A10: Publishing rule | B10: Only publish rankings after the verified source pack yields ranked rows and the audit passes.
A12: Current validation issues
A13: No source-pack validation issues currently detected.
A15: Suggested workflow
A16: 1. Fill country context rows first from official sources.
A17: 2. Use Field_Source_Guide and City_Source_Playbook before touching City_Source_Rows.
A18: 3. Fill city inputs with source URLs and dates attached to each pillar trail.
A19: 4. Re-import or keep editing in Google Sheets until the Leaderboard starts producing ranked rows.
A20: 5. Sync the same values back into the verified-source CSV pack for build-time publication.
A22: Internal reference layer
A23: Economist_Reference | B23: Auto-extracted from The World in Numbers PDF for analyst speed only. Do not treat these values as publishable scoring inputs.
A24: Economist_Match_Review | B24: One review row per SLIC country. Promote nothing automatically into Country_Context; every value still needs a trusted non-reference source.
A25: Reference-only provider rule | B25: economist_world_in_numbers is Tier 4 and reference_only=true, so it cannot make the public ranking publishable on its own.

Sheet Source_Coverage
A1: Source Coverage Dashboard
A3: Overall
A4: Metric | B4: Filled | C4: Total | D4: Completion
A5: Country_Context completion | B5: 359 | C5: 378 | D5: 95.0%
A6: City_Inputs completion | B6: 8 | C6: 2652 | D6: 0.3%
A7: Curated city playbook rows | B7: 52 | C7: 52 | D7: 100.0%
A8: Current city universe | B8: 102 | C8: 102 | D8: 100.0%
A11: Country Field Coverage
A12: Field | B12: Filled | C12: Total | D12: Completion
A13: GDP per capita (PPP) | B13: 62 | C13: 63 | D13: 98.4%
A14: GDP growth | B14: 62 | C14: 63 | D14: 98.4%
A15: Gini coefficient | B15: 55 | C15: 63 | D15: 87.3%
A16: PPP private consumption factor | B16: 62 | C16: 63 | D16: 98.4%
A17: Tax rate assumption | B17: 57 | C17: 63 | D17: 90.5%
A18: Household debt proxy | B18: 61 | C18: 63 | D18: 96.8%
A20: Italy Spotlight
A21: Target | B21: Filled | C21: Total | D21: Completion
A22: Italy Country_Context | B22: 6 | C22: 6 | D22: 100.0%
A23: Milan City_Inputs | B23: 8 | C23: 26 | D23: 30.8%
A24: Bologna City_Inputs | B24: 0 | C24: 26 | D24: 0.0%
A26: City Field Coverage
A27: Field | B27: Filled | C27: Total | D27: Completion
A28: Gross income | B28: 1 | C28: 102 | D28: 1.0%
A29: Rent | B29: 0 | C29: 102 | D29: 0.0%
A30: Utilities | B30: 0 | C30: 102 | D30: 0.0%
A31: Transit cost | B31: 1 | C31: 102 | D31: 1.0%
A32: Internet cost | B32: 0 | C32: 102 | D32: 0.0%
A33: Food cost | B33: 0 | C33: 102 | D33: 0.0%
A34: Housing burden raw | B34: 0 | C34: 102 | D34: 0.0%
A35: Household debt burden raw | B35: 0 | C35: 102 | D35: 0.0%
A36: Working time pressure raw | B36: 0 | C36: 102 | D36: 0.0%
A37: Suicide or mental strain raw | B37: 0 | C37: 102 | D37: 0.0%
A38: Personal safety raw | B38: 1 | C38: 102 | D38: 1.0%
A39: Transit access and commute raw | B39: 1 | C39: 102 | D39: 1.0%
... A53: Visitor flow context raw | B53: 1 | C53: 102 | D53: 1.0%

Sheet README
A1: SLIC Scoring Workbook
A3: Purpose | B3: This workbook is the operational source of truth for the global SLIC city ranking. Enter or import data into Country_Context and City_Inputs, then review Scores, Leaderboard, Region_Comparison, and the Thai-specific scaffold.
A4: Official formula | B4: SLIC(c) = 0.25 Pressure + 0.22 DailyViability + 0.18 HumanCapability + 0.15 Community + 0.20 CreativeVitality
A5: Disposable income term | B5: DI_ppp = ((gross_income x (1 - tax_rate)) - rent - utilities - transit - internet - food) / ppp_private_consumption
A6: Normalization | B6: Each scored input is winsorized at the 5th and 95th percentiles, then converted to a 0-100 score. Harmful variables such as crime, debt, suicide, PM2.5, and administrative friction are reverse-scored.
A7: Coverage rules | B7: A city is Ranked only when overall weighted coverage is at least 50% and every pillar clears the 35% minimum. Coverage grades: A >= 75%, B = 50-74%, C = 35-49%, below 35% = Watchlist.
A8: Source hierarchy | B8: Tier 1 city/metro official data > Tier 2 subnational official data > Tier 3 national and international official data > Tier 4 audited secondary and experimental layers.
A9: Doctrinal rule: safety | B9: Safety is scored by harm and victimization outcomes, never by camera count or visible control hardware.
A10: Doctrinal rule: tolerance | B10: Tolerance is scored through low-friction coexistence and real personal freedom, not symbolic branding proxies.
A11: Doctrinal rule: visitor flows | B11: Visitor flow is contextual only. It should be reviewed against crime, civic strain, and public-life quality rather than treated as an automatic positive.
A12: Country context | B12: GDP per capita PPP, GDP growth, Gini coefficient, PPP private consumption, and user-supplied tax rate are visible in Country_Context. GDP terms are capped context inputs, not headline determinants.
A13: How tax works | B13: Populate tax_rate_assumption in Country_Context as a decimal such as 0.18. City_Inputs pulls that value automatically into tax_rate_context and recomputes di_ppp_raw.
A14: Region comparison | B14: Region_Comparison summarizes ranked city counts and average scores by cohort so Europe, Asia, the Americas, Africa, the Middle East, and Oceania can be compared cleanly.
A15: Thai companion | B15: Thai_Ranking_Scaffold is a separate sheet for a Thailand-only ranking. It emphasizes province GDP per capita, pollution, hospitals, schools, infrastructure, income, longevity, and competitiveness.
A18: Coverage thresholds
A19: ranked_min_overall | B19: 0.5
A20: ranked_min_pillar | B20: 0.35
A21: grade_a_min | B21: 0.75
A22: grade_b_min | B22: 0.5
A23: grade_c_min | B23: 0.35
A26: Source tiers
A27: Tier 1 | B27: City and metro official data | C27: Open-data portals, utility regulators, transit feeds, hospital quality releases, and city statistical offices.
A28: Tier 2 | B28: State, province, and subnational official data | C28: Regional statistical offices, metropolitan observatories, and subnational administrative datasets.
A29: Tier 3 | B29: National and international official datasets | C29: World Bank, WHO, ILO, UNESCO UIS, OECD, WIPO, and WHO/UNICEF JMP.
A30: Tier 4 | B30: Audited secondary and experimental layers | C30: OpenAQ, M-Lab, social listening, crowdsourced cost layers, and city testimony with visible caveats.

Sheet Metric_Catalog
A1: metric_id | B1: metric_name | C1: pillar_id | D1: pillar_name | E1: pillar_weight | F1: metric_weight | G1: directionality | H1: scoring_role | I1: requiredness | J1: data_level | K1: source_priority | L1: workbook_input | M1: notes
A2: disposable_income_ppp | B2: Tax-adjusted PPP disposable income | C2: pressure | D2: Pressure, Affordability, and Room to Live | E2: 25 | F2: 9 | G2: positive | H2: scored | I2: core | J2: city_or_metro_with_country_context | K2: Tier 1 city/metro > Tier 2 subnational > Tier 3 national/international > Tier 4 audited secondary | L2: di_ppp_raw | M2: Derived from gross income, tax, rent, utilities, transit, internet, food, and PPP private consumption.
A3: housing_burden | B3: Housing burden | C3: pressure | D3: Pressure, Affordability, and Room to Live | E3: 25 | F3: 5 | G3: negative | H3: scored | I3: core | J3: city_or_metro | K3: Tier 1 city/metro > Tier 2 subnational > Tier 3 national/international > Tier 4 audited secondary | L3: housing_burden_raw | M3: Higher rent or housing cost share scores worse.
A4: household_debt_burden | B4: Household debt burden | C4: pressure | D4: Pressure, Affordability, and Room to Live | E4: 25 | F4: 4 | G4: negative | H4: scored | I4: core | J4: city_with_country_proxy_fallback | K4: Tier 1 city/metro > Tier 2 subnational > Tier 3 country debt proxy > Tier 4 audited secondary | L4: household_debt_effective_raw | M4: Uses country proxy when city debt burden is unavailable.
A5: working_time_pressure | B5: Working time pressure | C5: pressure | D5: Pressure, Affordability, and Room to Live | E5: 25 | F5: 4 | G5: negative | H5: scored | I5: core | J5: city_or_metro_with_subnational_fallback | K5: Tier 1 city/metro > Tier 2 subnational > Tier 3 ILO/national > Tier 4 audited secondary | L5: working_time_pressure_raw | M5: Higher weekly-hours and overwork prevalence score worse.
A6: suicide_mental_strain | B6: Suicide and severe mental strain | C6: pressure | D6: Pressure, Affordability, and Room to Live | E6: 25 | F6: 3 | G6: negative | H6: scored | I6: core | J6: city_or_metro_with_subnational_fallback | K6: Tier 1 city/metro > Tier 2 subnational > Tier 3 WHO/national > Tier 4 audited secondary | L6: suicide_mental_strain_raw | M6: Lower suicide or equivalent severe-strain rates score better.
A7: personal_safety | B7: Personal safety | C7: viability | D7: Daily Viability and Convenience | E7: 22 | F7: 5 | G7: negative | H7: scored | I7: core | J7: city_or_metro | K7: Tier 1 city/metro > Tier 2 subnational > Tier 3 national/international > Tier 4 audited secondary | L7: personal_safety_raw | M7: Enter a harm-and-victimization index or rate. Camera counts do not score.
A8: transit_access_commute | B8: Transit access and commute burden | C8: viability | D8: Daily Viability and Convenience | E8: 22 | F8: 5 | G8: positive | H8: scored | I8: core | J8: city_or_metro | K8: Tier 1 city/metro > Tier 2 GTFS/subnational > Tier 3 national/international > Tier 4 audited secondary | L8: transit_access_commute_raw | M8: Enter a composite where better access and lower burden push the value upward.
A9: clean_air | B9: Clean air | C9: viability | D9: Daily Viability and Convenience | E9: 22 | F9: 4 | G9: negative | H9: scored | I9: core | J9: city_or_metro | K9: Tier 1 city/metro > Tier 3 WHO/OpenAQ/national > Tier 4 audited secondary | L9: clean_air_raw | M9: Lower PM2.5 or pollution exposure scores better.
A10: water_sanitation_utility | B10: Water, sanitation, and utility reliability | C10: viability | D10: Daily Viability and Convenience | E10: 22 | F10: 4 | G10: positive | H10: scored | I10: core | J10: city_or_metro_with_country_fallback | K10: Tier 1 city/metro > Tier 2 subnational > Tier 3 JMP/national > Tier 4 audited secondary | L10: water_sanitation_utility_raw | M10: Enter a composite where safer access and higher reliability score better.
A11: digital_infrastructure | B11: Digital infrastructure | C11: viability | D11: Daily Viability and Convenience | E11: 22 | F11: 4 | G11: positive | H11: scored | I11: core | J11: city_or_metro_with_country_fallback | K11: Tier 1 city/metro > Tier 2 subnational > Tier 3 OECD/World Bank/M-Lab > Tier 4 audited secondary | L11: digital_infrastructure_raw | M11: Higher broadband quality, affordability, and fibre readiness score better.
A12: healthcare_quality | B12: Healthcare quality | C12: capability | D12: Human Capability | E12: 18 | F12: 8 | G12: positive | H12: scored | I12: core | J12: city_or_metro_with_country_context | K12: Tier 1 city/metro > Tier 2 subnational > Tier 3 WHO/OECD/national > Tier 4 audited secondary | L12: healthcare_quality_raw | M12: Higher effective-care access and outcome quality score better.
A13: education_quality | B13: Education quality | C13: capability | D13: Human Capability | E13: 18 | F13: 6 | G13: positive | H13: scored | I13: core | J13: city_or_metro_with_country_context | K13: Tier 1 city/metro > Tier 2 subnational > Tier 3 UNESCO/OECD/World Bank > Tier 4 audited secondary | L13: education_quality_raw | M13: Higher learning quality and skills formation score better.
... A25: visitor_flow_context | B25: Visitor flow context | C25: community | D25: Community and Openness | E25: 15 | F25: 0 | G25: contextual | H25: context_only | I25: supporting | J25: city_or_metro | K25: Tier 1 tourism/open mobility > Tier 4 audited secondary | L25: visitor_flow_context_raw | M25: Visible on the workbook and leaderboard context layer but not scored directly.

Sheet City_Universe
A1: city_id | B1: display_name | C1: fua_name | D1: country | E1: cohort | F1: city_type | G1: manifest_status | H1: inclusion_rationale
A2: th-bangkok | B2: Bangkok | C2: Bangkok Metropolitan Region | D2: Thailand | E2: Southeast Asia | F2: primary | G2: locked | H2: User anchor and regional benchmark for hospitality, economic dynamism, and affordability-pressure tradeoffs.
A3: sg-singapore | B3: Singapore | C3: Singapore | D3: Singapore | E3: Southeast Asia | F3: primary | G3: locked | H3: Global convenience benchmark included to test how systems quality interacts with pressure, cost, and meaning.
A4: my-kuala-lumpur | B4: Kuala Lumpur | C4: Klang Valley | D4: Malaysia | E4: Southeast Asia | F4: primary | G4: locked | H4: User anchor and regional economic core with strong competitiveness, connectivity, and mixed affordability.
A5: id-jakarta | B5: Jakarta | C5: Jakarta Metropolitan Area | D5: Indonesia | E5: Southeast Asia | F5: primary | G5: provisional | H5: Necessary Southeast Asian benchmark for scale, competitiveness, and infrastructure-pressure tradeoffs.
A6: ph-makati | B6: Makati | C6: Metro Manila Core Business District | D6: Philippines | E6: Southeast Asia | F6: primary | G6: provisional | H6: Metro-core Philippine test case included for business density, services, and lived-affordability stress.
A7: my-george-town | B7: George Town | C7: Penang Conurbation | D7: Malaysia | E7: Southeast Asia | F7: secondary | G7: locked | H7: User anchor for semiconductor economy, cultural texture, and secondary-city livability.
A8: th-phuket | B8: Phuket | C8: Phuket Island Urban Area | D8: Thailand | E8: Southeast Asia | F8: secondary | G8: locked | H8: User anchor and tourism-livability stress test for cost, safety, and service quality.
A9: th-chiang-mai | B9: Chiang Mai | C9: Chiang Mai Metropolitan Area | D9: Thailand | E9: Southeast Asia | F9: secondary | G9: locked | H9: User anchor for creativity, secondary-city ambition, and lifestyle viability.
A10: my-kuching | B10: Kuching | C10: Greater Kuching | D10: Malaysia | E10: Southeast Asia | F10: secondary | G10: locked | H10: User anchor included as a calmer secondary-city comparator with strong everyday livability appeal.
A11: th-hat-yai | B11: Hat Yai | C11: Hat Yai-Songkhla Urban Area | D11: Thailand | E11: Southeast Asia | F11: secondary | G11: provisional | H11: Southern Thai trade and services challenger included to test regional depth beyond capital-city bias.
A12: tw-taipei | B12: Taipei | C12: Taipei-Keelung-Taoyuan Metropolitan Area | D12: Taiwan | E12: East Asia | F12: primary | G12: locked | H12: High-systems, high-street-life benchmark aligned with earlier SLIC discussion.
... A103: fj-suva | B103: Suva | C103: Greater Suva | D103: Fiji | E103: Oceania | F103: secondary | G103: locked | H103: Pacific regional challenger included so Oceania is not reduced to Australia and New Zealand alone.

Sheet Country_Context
A1: country | B1: gdp_per_capita_ppp | C1: gdp_growth | D1: gini_coefficient | E1: ppp_private_consumption | F1: tax_rate_assumption | G1: household_debt_proxy | H1: source_url | I1: source_tier | J1: update_date | K1: notes
A2: Thailand | B2: 24712.07 | C2: 2.5418 | D2: 33.5 | E2: 10.945576 | F2: 0.152577 | G2: 115.1054 | H2: https://api.worldbank.org/v2/country/THA/indicator/NY.GDP.PCAP.PP.CD?format=json&mrv=30 | https://api.worldbank.org/v2/country/THA/indicator/NY.GDP.MKTP.KD.ZG?format=json&mrv=30 | https://api.worldbank.org/v2/country/THA/indicator/SI.POV.GINI?format=json&mrv=30 | +3 more | I2: Tier 3 | J2: 2024-12-31 | K2: providers=world_bank; fields=gdp_per_capita_ppp, gdp_growth, gini_coefficient, ppp_private_consumption; +2 additional fields
A3: Singapore | B3: 150689.3 | C3: 4.388 | E3: 1.04203 | F3: 0.141917 | G3: 129.1908 | H3: https://api.worldbank.org/v2/country/SGP/indicator/NY.GDP.PCAP.PP.CD?format=json&mrv=30 | https://api.worldbank.org/v2/country/SGP/indicator/NY.GDP.MKTP.KD.ZG?format=json&mrv=30 | https://api.worldbank.org/v2/country/SGP/indicator/PA.NUS.PRVT.PP?format=json&mrv=30 | +2 more | I3: Tier 3 | J3: 2024-12-31 | K3: providers=world_bank; fields=gdp_per_capita_ppp, gdp_growth, ppp_private_consumption, tax_rate_assumption; +1 additional fields
A4: Malaysia | B4: 38779.28 | C4: 5.1055 | D4: 40.7 | E4: 1.449227 | F4: 0.125648 | G4: 116.0773 | H4: https://api.worldbank.org/v2/country/MYS/indicator/NY.GDP.PCAP.PP.CD?format=json&mrv=30 | https://api.worldbank.org/v2/country/MYS/indicator/NY.GDP.MKTP.KD.ZG?format=json&mrv=30 | https://api.worldbank.org/v2/country/MYS/indicator/SI.POV.GINI?format=json&mrv=30 | +3 more | I4: Tier 3 | J4: 2024-12-31 | K4: providers=world_bank; fields=gdp_per_capita_ppp, gdp_growth, gini_coefficient, ppp_private_consumption; +2 additional fields
A5: Indonesia | B5: 16448.28 | C5: 5.0303 | D5: 34.9 | E5: 5104.9843 | F5: 0.110578 | G5: 31.7861 | H5: https://api.worldbank.org/v2/country/IDN/indicator/NY.GDP.PCAP.PP.CD?format=json&mrv=30 | https://api.worldbank.org/v2/country/IDN/indicator/NY.GDP.MKTP.KD.ZG?format=json&mrv=30 | https://api.worldbank.org/v2/country/IDN/indicator/SI.POV.GINI?format=json&mrv=30 | +3 more | I5: Tier 3 | J5: 2024-12-31 | K5: providers=world_bank; fields=gdp_per_capita_ppp, gdp_growth, gini_coefficient, ppp_private_consumption; +2 additional fields
A6: Philippines | B6: 11794.14 | C6: 5.692 | D6: 39.3 | E6: 20.743506 | F6: 0.141044 | G6: 49.8137 | H6: https://api.worldbank.org/v2/country/PHL/indicator/NY.GDP.PCAP.PP.CD?format=json&mrv=30 | https://api.worldbank.org/v2/country/PHL/indicator/NY.GDP.MKTP.KD.ZG?format=json&mrv=30 | https://api.worldbank.org/v2/country/PHL/indicator/SI.POV.GINI?format=json&mrv=30 | +3 more | I6: Tier 3 | J6: 2024-12-31 | K6: providers=world_bank; fields=gdp_per_capita_ppp, gdp_growth, gini_coefficient, ppp_private_consumption; +2 additional fields
A7: Taiwan | K7: Populate official country context inputs before ranking.
A8: South Korea | B8: 61051.35 | C8: 2.0036 | D8: 32.9 | E8: 872.46874 | F8: 0.145991 | G8: 160.3472 | H8: https://api.worldbank.org/v2/country/KOR/indicator/NY.GDP.PCAP.PP.CD?format=json&mrv=30 | https://api.worldbank.org/v2/country/KOR/indicator/NY.GDP.MKTP.KD.ZG?format=json&mrv=30 | https://api.worldbank.org/v2/country/KOR/indicator/SI.POV.GINI?format=json&mrv=30 | +3 more | I8: Tier 3 | J8: 2024-12-31 | K8: providers=world_bank; fields=gdp_per_capita_ppp, gdp_growth, gini_coefficient, ppp_private_consumption; +2 additional fields
A9: China | B9: 27104.87 | C9: 4.9774 | D9: 36 | E9: 3.550789 | F9: 0.076382 | G9: 194.166 | H9: https://api.worldbank.org/v2/country/CHN/indicator/NY.GDP.PCAP.PP.CD?format=json&mrv=30 | https://api.worldbank.org/v2/country/CHN/indicator/NY.GDP.MKTP.KD.ZG?format=json&mrv=30 | https://api.worldbank.org/v2/country/CHN/indicator/SI.POV.GINI?format=json&mrv=30 | +3 more | I9: Tier 3 | J9: 2024-12-31 | K9: providers=world_bank; fields=gdp_per_capita_ppp, gdp_growth, gini_coefficient, ppp_private_consumption; +2 additional fields
A10: Japan | B10: 52039.17 | C10: 0.1043 | D10: 32.3 | E10: 99.384798 | G10: 123.1289 | H10: https://api.worldbank.org/v2/country/JPN/indicator/NY.GDP.PCAP.PP.CD?format=json&mrv=30 | https://api.worldbank.org/v2/country/JPN/indicator/NY.GDP.MKTP.KD.ZG?format=json&mrv=30 | https://api.worldbank.org/v2/country/JPN/indicator/SI.POV.GINI?format=json&mrv=30 | +2 more | I10: Tier 3 | J10: 2024-12-31 | K10: providers=world_bank; fields=gdp_per_capita_ppp, gdp_growth, gini_coefficient, ppp_private_consumption; +1 additional fields
A11: India | B11: 11159.99 | C11: 6.4948 | D11: 25.5 | E11: 19.896916 | F11: 0.067344 | G11: 50.1422 | H11: https://api.worldbank.org/v2/country/IND/indicator/NY.GDP.PCAP.PP.CD?format=json&mrv=30 | https://api.worldbank.org/v2/country/IND/indicator/NY.GDP.MKTP.KD.ZG?format=json&mrv=30 | https://api.worldbank.org/v2/country/IND/indicator/SI.POV.GINI?format=json&mrv=30 | +3 more | I11: Tier 3 | J11: 2024-12-31 | K11: providers=world_bank; fields=gdp_per_capita_ppp, gdp_growth, gini_coefficient, ppp_private_consumption; +2 additional fields
A12: Sri Lanka | B12: 15632.59 | C12: 5.0087 | D12: 37.7 | E12: 87.489315 | F12: 0.099219 | G12: 46.8716 | H12: https://api.worldbank.org/v2/country/LKA/indicator/NY.GDP.PCAP.PP.CD?format=json&mrv=30 | https://api.worldbank.org/v2/country/LKA/indicator/NY.GDP.MKTP.KD.ZG?format=json&mrv=30 | https://api.worldbank.org/v2/country/LKA/indicator/SI.POV.GINI?format=json&mrv=30 | +3 more | I12: Tier 3 | J12: 2024-12-31 | K12: providers=world_bank; fields=gdp_per_capita_ppp, gdp_growth, gini_coefficient, ppp_private_consumption; +2 additional fields
A13: Bangladesh | B13: 9646.77 | C13: 4.2233 | D13: 30.9 | E13: 32.990539 | F13: 0.076424 | G13: 35.7061 | H13: https://api.worldbank.org/v2/country/BGD/indicator/NY.GDP.PCAP.PP.CD?format=json&mrv=30 | https://api.worldbank.org/v2/country/BGD/indicator/NY.GDP.MKTP.KD.ZG?format=json&mrv=30 | https://api.worldbank.org/v2/country/BGD/indicator/SI.POV.GINI?format=json&mrv=30 | +3 more | I13: Tier 3 | J13: 2024-12-31 | K13: providers=world_bank; fields=gdp_per_capita_ppp, gdp_growth, gini_coefficient, ppp_private_consumption; +2 additional fields
A14: Pakistan | B14: 6252.12 | C14: 3.049 | D14: 29.6 | E14: 64.860994 | G14: 11.3901 | H14: https://api.worldbank.org/v2/country/PAK/indicator/NY.GDP.PCAP.PP.CD?format=json&mrv=30 | https://api.worldbank.org/v2/country/PAK/indicator/NY.GDP.MKTP.KD.ZG?format=json&mrv=30 | https://api.worldbank.org/v2/country/PAK/indicator/SI.POV.GINI?format=json&mrv=30 | +2 more | I14: Tier 3 | J14: 2024-12-31 | K14: providers=world_bank; fields=gdp_per_capita_ppp, gdp_growth, gini_coefficient, ppp_private_consumption; +1 additional fields
A15: Nepal | B15: 5736.62 | C15: 3.6654 | D15: 30 | E15: 35.285741 | F15: 0.139449 | G15: 91.9385 | H15: https://api.worldbank.org/v2/country/NPL/indicator/NY.GDP.PCAP.PP.CD?format=json&mrv=30 | https://api.worldbank.org/v2/country/NPL/indicator/NY.GDP.MKTP.KD.ZG?format=json&mrv=30 | https://api.worldbank.org/v2/country/NPL/indicator/SI.POV.GINI?format=json&mrv=30 | +3 more | I15: Tier 3 | J15: 2024-12-31 | K15: providers=world_bank; fields=gdp_per_capita_ppp, gdp_growth, gini_coefficient, ppp_private_consumption; +2 additional fields
A16: Bhutan | B16: 16215.15 | C16: 4.6322 | D16: 28.5 | E16: 20.878112 | F16: 0.122846 | G16: 51.8935 | H16: https://api.worldbank.org/v2/country/BTN/indicator/NY.GDP.PCAP.PP.CD?format=json&mrv=30 | https://api.worldbank.org/v2/country/BTN/indicator/NY.GDP.MKTP.KD.ZG?format=json&mrv=30 | https://api.worldbank.org/v2/country/BTN/indicator/SI.POV.GINI?format=json&mrv=30 | +3 more | I16: Tier 3 | J16: 2024-12-31 | K16: providers=world_bank; fields=gdp_per_capita_ppp, gdp_growth, gini_coefficient, ppp_private_consumption; +2 additional fields
A17: Maldives | B17: 26182.78 | C17: 3.4944 | D17: 29.3 | E17: 9.455282 | F17: 0.194532 | G17: 31.5415 | H17: https://api.worldbank.org/v2/country/MDV/indicator/NY.GDP.PCAP.PP.CD?format=json&mrv=30 | https://api.worldbank.org/v2/country/MDV/indicator/NY.GDP.MKTP.KD.ZG?format=json&mrv=30 | https://api.worldbank.org/v2/country/MDV/indicator/SI.POV.GINI?format=json&mrv=30 | +3 more | I17: Tier 3 | J17: 2024-12-31 | K17: providers=world_bank; fields=gdp_per_capita_ppp, gdp_growth, gini_coefficient, ppp_private_consumption; +2 additional fields
A18: France | B18: 62556.92 | C18: 1.1905 | D18: 31.8 | E18: 0.716934 | F18: 0.23077 | G18: 103.9081 | H18: https://api.worldbank.org/v2/country/FRA/indicator/NY.GDP.PCAP.PP.CD?format=json&mrv=30 | https://api.worldbank.org/v2/country/FRA/indicator/NY.GDP.MKTP.KD.ZG?format=json&mrv=30 | https://api.worldbank.org/v2/country/FRA/indicator/SI.POV.GINI?format=json&mrv=30 | +3 more | I18: Tier 3 | J18: 2024-12-31 | K18: providers=world_bank; fields=gdp_per_capita_ppp, gdp_growth, gini_coefficient, ppp_private_consumption; +2 additional fields
A19: Austria | B19: 73911.44 | C19: -0.6591 | D19: 31.2 | E19: 0.720487 | F19: 0.256407 | G19: 81.4953 | H19: https://api.worldbank.org/v2/country/AUT/indicator/NY.GDP.PCAP.PP.CD?format=json&mrv=30 | https://api.worldbank.org/v2/country/AUT/indicator/NY.GDP.MKTP.KD.ZG?format=json&mrv=30 | https://api.worldbank.org/v2/country/AUT/indicator/SI.POV.GINI?format=json&mrv=30 | +3 more | I19: Tier 3 | J19: 2024-12-31 | K19: providers=world_bank; fields=gdp_per_capita_ppp, gdp_growth, gini_coefficient, ppp_private_consumption; +2 additional fields
A20: Switzerland | B20: 96497.69 | C20: 1.3023 | D20: 33.8 | E20: 1.062369 | F20: 0.090036 | G20: 170.3782 | H20: https://api.worldbank.org/v2/country/CHE/indicator/NY.GDP.PCAP.PP.CD?format=json&mrv=30 | https://api.worldbank.org/v2/country/CHE/indicator/NY.GDP.MKTP.KD.ZG?format=json&mrv=30 | https://api.worldbank.org/v2/country/CHE/indicator/SI.POV.GINI?format=json&mrv=30 | +3 more | I20: Tier 3 | J20: 2024-12-31 | K20: providers=world_bank; fields=gdp_per_capita_ppp, gdp_growth, gini_coefficient, ppp_private_consumption; +2 additional fields
A21: Netherlands | B21: 86173.63 | C21: 1.081 | D21: 25.7 | E21: 0.74195 | F21: 0.25254 | G21: 82.3297 | H21: https://api.worldbank.org/v2/country/NLD/indicator/NY.GDP.PCAP.PP.CD?format=json&mrv=30 | https://api.worldbank.org/v2/country/NLD/indicator/NY.GDP.MKTP.KD.ZG?format=json&mrv=30 | https://api.worldbank.org/v2/country/NLD/indicator/SI.POV.GINI?format=json&mrv=30 | +3 more | I21: Tier 3 | J21: 2024-12-31 | K21: providers=world_bank; fields=gdp_per_capita_ppp, gdp_growth, gini_coefficient, ppp_private_consumption; +2 additional fields
A22: Denmark | B22: 81878.23 | C22: 3.4778 | D22: 29.9 | E22: 6.764411 | F22: 0.315935 | G22: 144.0931 | H22: https://api.worldbank.org/v2/country/DNK/indicator/NY.GDP.PCAP.PP.CD?format=json&mrv=30 | https://api.worldbank.org/v2/country/DNK/indicator/NY.GDP.MKTP.KD.ZG?format=json&mrv=30 | https://api.worldbank.org/v2/country/DNK/indicator/SI.POV.GINI?format=json&mrv=30 | +3 more | I22: Tier 3 | J22: 2024-12-31 | K22: providers=world_bank; fields=gdp_per_capita_ppp, gdp_growth, gini_coefficient, ppp_private_consumption; +2 additional fields
A23: Italy | B23: 62014.27 | C23: 0.6927 | D23: 34.3 | E23: 0.625157 | F23: 0.24708 | G23: 59.3116 | H23: https://api.worldbank.org/v2/country/ITA/indicator/NY.GDP.PCAP.PP.CD?format=json&mrv=30 | https://api.worldbank.org/v2/country/ITA/indicator/NY.GDP.MKTP.KD.ZG?format=json&mrv=30 | https://api.worldbank.org/v2/country/ITA/indicator/SI.POV.GINI?format=json&mrv=30 | +3 more | I23: Tier 3 | J23: 2024-12-31 | K23: providers=world_bank; fields=gdp_per_capita_ppp, gdp_growth, gini_coefficient, ppp_private_consumption; +2 additional fields
A24: Portugal | B24: 51679.89 | C24: 2.1397 | D24: 33.9 | E24: 0.558749 | F24: 0.226188 | G24: 77.1375 | H24: https://api.worldbank.org/v2/country/PRT/indicator/NY.GDP.PCAP.PP.CD?format=json&mrv=30 | https://api.worldbank.org/v2/country/PRT/indicator/NY.GDP.MKTP.KD.ZG?format=json&mrv=30 | https://api.worldbank.org/v2/country/PRT/indicator/SI.POV.GINI?format=json&mrv=30 | +3 more | I24: Tier 3 | J24: 2024-12-31 | K24: providers=world_bank; fields=gdp_per_capita_ppp, gdp_growth, gini_coefficient, ppp_private_consumption; +2 additional fields
A25: Estonia | B25: 49968.71 | C25: -0.09 | D25: 30.7 | E25: 0.646078 | F25: 0.21329 | G25: 60.5329 | H25: https://api.worldbank.org/v2/country/EST/indicator/NY.GDP.PCAP.PP.CD?format=json&mrv=30 | https://api.worldbank.org/v2/country/EST/indicator/NY.GDP.MKTP.KD.ZG?format=json&mrv=30 | https://api.worldbank.org/v2/country/EST/indicator/SI.POV.GINI?format=json&mrv=30 | +3 more | I25: Tier 3 | J25: 2024-12-31 | K25: providers=world_bank; fields=gdp_per_capita_ppp, gdp_growth, gini_coefficient, ppp_private_consumption; +2 additional fields
A26: Finland | B26: 65378.38 | C26: 0.4162 | D26: 27.4 | E26: 0.788236 | F26: 0.253757 | G26: 90.8647 | H26: https://api.worldbank.org/v2/country/FIN/indicator/NY.GDP.PCAP.PP.CD?format=json&mrv=30 | https://api.worldbank.org/v2/country/FIN/indicator/NY.GDP.MKTP.KD.ZG?format=json&mrv=30 | https://api.worldbank.org/v2/country/FIN/indicator/SI.POV.GINI?format=json&mrv=30 | +3 more | I26: Tier 3 | J26: 2024-12-31 | K26: providers=world_bank; fields=gdp_per_capita_ppp, gdp_growth, gini_coefficient, ppp_private_consumption; +2 additional fields
... A37: Costa Rica | B37: 31106.76 | C37: 4.3212 | D37: 45.8 | E37: 328.04659 | F37: 0.139115 | G37: 50.9742 | H37: https://api.worldbank.org/v2/country/CRI/indicator/NY.GDP.PCAP.PP.CD?format=json&mrv=30 | https://api.worldbank.org/v2/country/CRI/indicator/NY.GDP.MKTP.KD.ZG?format=json&mrv=30 | https://api.worldbank.org/v2/country/CRI/indicator/SI.POV.GINI?format=json&mrv=30 | +3 more | I37: Tier 3 | J37: 2024-12-31 | K37: providers=world_bank; fields=gdp_per_capita_ppp, gdp_growth, gini_coefficient, ppp_private_consumption; +2 additional fields
A38: Puerto Rico | B38: 50247.85 | C38: 3.1771 | E38: 0.896932 | H38: https://api.worldbank.org/v2/country/PRI/indicator/NY.GDP.PCAP.PP.CD?format=json&mrv=30 | https://api.worldbank.org/v2/country/PRI/indicator/NY.GDP.MKTP.KD.ZG?format=json&mrv=30 | https://api.worldbank.org/v2/country/PRI/indicator/PA.NUS.PRVT.PP?format=json&mrv=30 | I38: Tier 3 | J38: 2024-12-31 | K38: providers=world_bank; fields=gdp_per_capita_ppp, gdp_growth, ppp_private_consumption
A39: Brazil | B39: 22338.48 | C39: 3.4193 | D39: 51.6 | E39: 2.524497 | F39: 0.154102 | G39: 75.6164 | H39: https://api.worldbank.org/v2/country/BRA/indicator/NY.GDP.PCAP.PP.CD?format=json&mrv=30 | https://api.worldbank.org/v2/country/BRA/indicator/NY.GDP.MKTP.KD.ZG?format=json&mrv=30 | https://api.worldbank.org/v2/country/BRA/indicator/SI.POV.GINI?format=json&mrv=30 | +3 more | I39: Tier 3 | J39: 2024-12-31 | K39: providers=world_bank; fields=gdp_per_capita_ppp, gdp_growth, gini_coefficient, ppp_private_consumption; +2 additional fields
A40: Argentina | B40: 30431.19 | C40: -1.3429 | D40: 42.4 | E40: 42.98624 | F40: 0.099289 | G40: 13.0788 | H40: https://api.worldbank.org/v2/country/ARG/indicator/NY.GDP.PCAP.PP.CD?format=json&mrv=30 | https://api.worldbank.org/v2/country/ARG/indicator/NY.GDP.MKTP.KD.ZG?format=json&mrv=30 | https://api.worldbank.org/v2/country/ARG/indicator/SI.POV.GINI?format=json&mrv=30 | +3 more | I40: Tier 3 | J40: 2024-12-31 | K40: providers=world_bank; fields=gdp_per_capita_ppp, gdp_growth, gini_coefficient, ppp_private_consumption; +2 additional fields
A41: Chile | B41: 36181.16 | C41: 2.6443 | D41: 43 | E41: 464.87603 | F41: 0.177194 | G41: 74.9355 | H41: https://api.worldbank.org/v2/country/CHL/indicator/NY.GDP.PCAP.PP.CD?format=json&mrv=30 | https://api.worldbank.org/v2/country/CHL/indicator/NY.GDP.MKTP.KD.ZG?format=json&mrv=30 | https://api.worldbank.org/v2/country/CHL/indicator/SI.POV.GINI?format=json&mrv=30 | +3 more | I41: Tier 3 | J41: 2024-12-31 | K41: providers=world_bank; fields=gdp_per_capita_ppp, gdp_growth, gini_coefficient, ppp_private_consumption; +2 additional fields
A42: Colombia | B42: 22349.44 | C42: 1.5983 | D42: 53.9 | E42: 1542.1938 | F42: 0.152812 | G42: 39.5117 | H42: https://api.worldbank.org/v2/country/COL/indicator/NY.GDP.PCAP.PP.CD?format=json&mrv=30 | https://api.worldbank.org/v2/country/COL/indicator/NY.GDP.MKTP.KD.ZG?format=json&mrv=30 | https://api.worldbank.org/v2/country/COL/indicator/SI.POV.GINI?format=json&mrv=30 | +3 more | I42: Tier 3 | J42: 2024-12-31 | K42: providers=world_bank; fields=gdp_per_capita_ppp, gdp_growth, gini_coefficient, ppp_private_consumption; +2 additional fields
A43: Peru | B43: 17802.42 | C43: 3.3039 | D43: 40.1 | E43: 1.94918 | F43: 0.159243 | G43: 45.668 | H43: https://api.worldbank.org/v2/country/PER/indicator/NY.GDP.PCAP.PP.CD?format=json&mrv=30 | https://api.worldbank.org/v2/country/PER/indicator/NY.GDP.MKTP.KD.ZG?format=json&mrv=30 | https://api.worldbank.org/v2/country/PER/indicator/SI.POV.GINI?format=json&mrv=30 | +3 more | I43: Tier 3 | J43: 2024-12-31 | K43: providers=world_bank; fields=gdp_per_capita_ppp, gdp_growth, gini_coefficient, ppp_private_consumption; +2 additional fields
A44: Uruguay | B44: 36417.87 | C44: 3.1083 | D44: 40 | E44: 29.298217 | F44: 0.181624 | G44: 31.0608 | H44: https://api.worldbank.org/v2/country/URY/indicator/NY.GDP.PCAP.PP.CD?format=json&mrv=30 | https://api.worldbank.org/v2/country/URY/indicator/NY.GDP.MKTP.KD.ZG?format=json&mrv=30 | https://api.worldbank.org/v2/country/URY/indicator/SI.POV.GINI?format=json&mrv=30 | +3 more | I44: Tier 3 | J44: 2024-12-31 | K44: providers=world_bank; fields=gdp_per_capita_ppp, gdp_growth, gini_coefficient, ppp_private_consumption; +2 additional fields
A45: United Arab Emirates | B45: 79228.74 | C45: 3.9918 | D45: 26.4 | E45: 2.56311 | F45: 0.006475 | G45: 67.9658 | H45: https://api.worldbank.org/v2/country/ARE/indicator/NY.GDP.PCAP.PP.CD?format=json&mrv=30 | https://api.worldbank.org/v2/country/ARE/indicator/NY.GDP.MKTP.KD.ZG?format=json&mrv=30 | https://api.worldbank.org/v2/country/ARE/indicator/SI.POV.GINI?format=json&mrv=30 | +3 more | I45: Tier 3 | J45: 2024-12-31 | K45: providers=world_bank; fields=gdp_per_capita_ppp, gdp_growth, gini_coefficient, ppp_private_consumption; +2 additional fields
A46: Qatar | B46: 126046.35 | C46: 2.3597 | D46: 35.1 | E46: 2.755487 | G46: 118.8652 | H46: https://api.worldbank.org/v2/country/QAT/indicator/NY.GDP.PCAP.PP.CD?format=json&mrv=30 | https://api.worldbank.org/v2/country/QAT/indicator/NY.GDP.MKTP.KD.ZG?format=json&mrv=30 | https://api.worldbank.org/v2/country/QAT/indicator/SI.POV.GINI?format=json&mrv=30 | +2 more | I46: Tier 3 | J46: 2024-12-31 | K46: providers=world_bank; fields=gdp_per_capita_ppp, gdp_growth, gini_coefficient, ppp_private_consumption; +1 additional fields
A47: Saudi Arabia | B47: 71375.37 | C47: 1.9965 | E47: 1.882361 | F47: 0.081847 | G47: 50.1376 | H47: https://api.worldbank.org/v2/country/SAU/indicator/NY.GDP.PCAP.PP.CD?format=json&mrv=30 | https://api.worldbank.org/v2/country/SAU/indicator/NY.GDP.MKTP.KD.ZG?format=json&mrv=30 | https://api.worldbank.org/v2/country/SAU/indicator/PA.NUS.PRVT.PP?format=json&mrv=30 | +2 more | I47: Tier 3 | J47: 2024-12-31 | K47: providers=world_bank; fields=gdp_per_capita_ppp, gdp_growth, ppp_private_consumption, tax_rate_assumption; +1 additional fields
A48: Israel | B48: 57235.78 | C48: 0.872 | D48: 37.9 | E48: 3.607983 | F48: 0.221364 | G48: 69.7497 | H48: https://api.worldbank.org/v2/country/ISR/indicator/NY.GDP.PCAP.PP.CD?format=json&mrv=30 | https://api.worldbank.org/v2/country/ISR/indicator/NY.GDP.MKTP.KD.ZG?format=json&mrv=30 | https://api.worldbank.org/v2/country/ISR/indicator/SI.POV.GINI?format=json&mrv=30 | +3 more | I48: Tier 3 | J48: 2024-12-31 | K48: providers=world_bank; fields=gdp_per_capita_ppp, gdp_growth, gini_coefficient, ppp_private_consumption; +2 additional fields
A49: Oman | B49: 41740.17 | C49: 1.6316 | E49: 0.184982 | G49: 59.7083 | H49: https://api.worldbank.org/v2/country/OMN/indicator/NY.GDP.PCAP.PP.CD?format=json&mrv=30 | https://api.worldbank.org/v2/country/OMN/indicator/NY.GDP.MKTP.KD.ZG?format=json&mrv=30 | https://api.worldbank.org/v2/country/OMN/indicator/PA.NUS.PRVT.PP?format=json&mrv=30 | +1 more | I49: Tier 3 | J49: 2024-12-31 | K49: providers=world_bank; fields=gdp_per_capita_ppp, gdp_growth, ppp_private_consumption, household_debt_proxy
A50: Bahrain | B50: 66941.24 | C50: 2.6038 | E50: 0.188671 | F50: 0.028232 | G50: 70.5501 | H50: https://api.worldbank.org/v2/country/BHR/indicator/NY.GDP.PCAP.PP.CD?format=json&mrv=30 | https://api.worldbank.org/v2/country/BHR/indicator/NY.GDP.MKTP.KD.ZG?format=json&mrv=30 | https://api.worldbank.org/v2/country/BHR/indicator/PA.NUS.PRVT.PP?format=json&mrv=30 | +2 more | I50: Tier 3 | J50: 2024-12-31 | K50: providers=world_bank; fields=gdp_per_capita_ppp, gdp_growth, ppp_private_consumption, tax_rate_assumption; +1 additional fields
...

Sheet City_Inputs
A1: city_id | B1: display_name | C1: country | D1: cohort | E1: city_type | F1: manifest_status | G1: gross_income | H1: rent | I1: utilities | J1: transit_cost | K1: internet_cost | L1: food_cost | M1: di_ppp_raw | N1: housing_burden_raw | O1: household_debt_burden_raw | P1: household_debt_effective_raw | Q1: working_time_pressure_raw | R1: suicide_mental_strain_raw | S1: personal_safety_raw | T1: transit_access_commute_raw | U1: clean_air_raw | V1: water_sanitation_utility_raw | W1: digital_infrastructure_raw | X1: healthcare_quality_raw | Y1: education_quality_raw | Z1: equal_opportunity_raw | AA1: hospitality_belonging_raw | AB1: tolerance_pluralism_raw | AC1: cultural_public_life_raw | AD1: entrepreneurial_dynamism_raw | AE1: innovation_research_intensity_raw | AF1: investment_signal_raw | AG1: administrative_investment_friction_raw | AH1: visitor_flow_context_raw | AI1: gdp_per_capita_ppp_context | AJ1: gdp_growth_context | AK1: gini_coefficient_context | AL1: ppp_private_consumption_context | AM1: tax_rate_context | AN1: household_debt_proxy_context | AO1: pressure_source_url | AP1: pressure_source_tier | AQ1: pressure_source_date | AR1: pressure_notes | AS1: viability_source_url | AT1: viability_source_tier | AU1: viability_source_date | AV1: viability_notes | AW1: capability_source_url | AX1: capability_source_tier | AY1: capability_source_date | AZ1: capability_notes | BA1: community_source_url | BB1: community_source_tier | BC1: community_source_date | BD1: community_notes | BE1: creative_source_url | BF1: creative_source_tier | BG1: creative_source_date | BH1: creative_notes
A2: th-bangkok | B2: Bangkok | C2: Thailand | D2: Southeast Asia | E2: primary | F2: locked | M2: =IF(OR($G2="",$H2="",$I2="",$J2="",$K2="",$L2="",$AL2="",$AM2=""),"",((($G2*(1-$AM2))-$H2-$I2-$J2-$K2-$L2)/$AL2)) | P2: =IF($O2<>"",$O2,$AN2) | AI2: =IFERROR(INDEX(Country_Context!$B$2:$B$64,MATCH($C2,Country_Context!$A$2:$A$64,0)),"") | AJ2: =IFERROR(INDEX(Country_Context!$C$2:$C$64,MATCH($C2,Country_Context!$A$2:$A$64,0)),"") | AK2: =IFERROR(INDEX(Country_Context!$D$2:$D$64,MATCH($C2,Country_Context!$A$2:$A$64,0)),"") | AL2: =IFERROR(INDEX(Country_Context!$E$2:$E$64,MATCH($C2,Country_Context!$A$2:$A$64,0)),"") | AM2: =IFERROR(INDEX(Country_Context!$F$2:$F$64,MATCH($C2,Country_Context!$A$2:$A$64,0)),"") | AN2: =IFERROR(INDEX(Country_Context!$G$2:$G$64,MATCH($C2,Country_Context!$A$2:$A$64,0)),"") | AO2: https://api.worldbank.org/v2/country/THA/indicator/PA.NUS.PRVT.PP?format=json&mrv=30 | https://api.worldbank.org/v2/country/THA/indicator/GC.TAX.TOTL.GD.ZS?format=json&mrv=30 | https://api.worldbank.org/v2/country/THA/indicator/FD.AST.PRVT.GD.ZS?format=json&mrv=30 | AP2: Tier 3 | AQ2: 2024-12-31 | AR2: providers=world_bank; fields=ppp_private_consumption, tax_rate_assumption, household_debt_proxy | AW2: https://api.worldbank.org/v2/country/THA/indicator/SI.POV.GINI?format=json&mrv=30 | AX2: Tier 3 | AY2: 2023-12-31 | AZ2: providers=world_bank; fields=gini_coefficient | BE2: https://api.worldbank.org/v2/country/THA/indicator/NY.GDP.PCAP.PP.CD?format=json&mrv=30 | https://api.worldbank.org/v2/country/THA/indicator/NY.GDP.MKTP.KD.ZG?format=json&mrv=30 | BF2: Tier 3 | BG2: 2024-12-31 | BH2: providers=world_bank; fields=gdp_per_capita_ppp, gdp_growth
A3: sg-singapore | B3: Singapore | C3: Singapore | D3: Southeast Asia | E3: primary | F3: locked | M3: =IF(OR($G3="",$H3="",$I3="",$J3="",$K3="",$L3="",$AL3="",$AM3=""),"",((($G3*(1-$AM3))-$H3-$I3-$J3-$K3-$L3)/$AL3)) | P3: =IF($O3<>"",$O3,$AN3) | AI3: =IFERROR(INDEX(Country_Context!$B$2:$B$64,MATCH($C3,Country_Context!$A$2:$A$64,0)),"") | AJ3: =IFERROR(INDEX(Country_Context!$C$2:$C$64,MATCH($C3,Country_Context!$A$2:$A$64,0)),"") | AK3: =IFERROR(INDEX(Country_Context!$D$2:$D$64,MATCH($C3,Country_Context!$A$2:$A$64,0)),"") | AL3: =IFERROR(INDEX(Country_Context!$E$2:$E$64,MATCH($C3,Country_Context!$A$2:$A$64,0)),"") | AM3: =IFERROR(INDEX(Country_Context!$F$2:$F$64,MATCH($C3,Country_Context!$A$2:$A$64,0)),"") | AN3: =IFERROR(INDEX(Country_Context!$G$2:$G$64,MATCH($C3,Country_Context!$A$2:$A$64,0)),"") | AO3: https://api.worldbank.org/v2/country/SGP/indicator/PA.NUS.PRVT.PP?format=json&mrv=30 | https://api.worldbank.org/v2/country/SGP/indicator/GC.TAX.TOTL.GD.ZS?format=json&mrv=30 | https://api.worldbank.org/v2/country/SGP/indicator/FD.AST.PRVT.GD.ZS?format=json&mrv=30 | AP3: Tier 3 | AQ3: 2024-12-31 | AR3: providers=world_bank; fields=ppp_private_consumption, tax_rate_assumption, household_debt_proxy | BE3: https://api.worldbank.org/v2/country/SGP/indicator/NY.GDP.PCAP.PP.CD?format=json&mrv=30 | https://api.worldbank.org/v2/country/SGP/indicator/NY.GDP.MKTP.KD.ZG?format=json&mrv=30 | BF3: Tier 3 | BG3: 2024-12-31 | BH3: providers=world_bank; fields=gdp_per_capita_ppp, gdp_growth
A4: my-kuala-lumpur | B4: Kuala Lumpur | C4: Malaysia | D4: Southeast Asia | E4: primary | F4: locked | M4: =IF(OR($G4="",$H4="",$I4="",$J4="",$K4="",$L4="",$AL4="",$AM4=""),"",((($G4*(1-$AM4))-$H4-$I4-$J4-$K4-$L4)/$AL4)) | P4: =IF($O4<>"",$O4,$AN4) | AI4: =IFERROR(INDEX(Country_Context!$B$2:$B$64,MATCH($C4,Country_Context!$A$2:$A$64,0)),"") | AJ4: =IFERROR(INDEX(Country_Context!$C$2:$C$64,MATCH($C4,Country_Context!$A$2:$A$64,0)),"") | AK4: =IFERROR(INDEX(Country_Context!$D$2:$D$64,MATCH($C4,Country_Context!$A$2:$A$64,0)),"") | AL4: =IFERROR(INDEX(Country_Context!$E$2:$E$64,MATCH($C4,Country_Context!$A$2:$A$64,0)),"") | AM4: =IFERROR(INDEX(Country_Context!$F$2:$F$64,MATCH($C4,Country_Context!$A$2:$A$64,0)),"") | AN4: =IFERROR(INDEX(Country_Context!$G$2:$G$64,MATCH($C4,Country_Context!$A$2:$A$64,0)),"") | AO4: https://api.worldbank.org/v2/country/MYS/indicator/PA.NUS.PRVT.PP?format=json&mrv=30 | https://api.worldbank.org/v2/country/MYS/indicator/GC.TAX.TOTL.GD.ZS?format=json&mrv=30 | https://api.worldbank.org/v2/country/MYS/indicator/FD.AST.PRVT.GD.ZS?format=json&mrv=30 | AP4: Tier 3 | AQ4: 2024-12-31 | AR4: providers=world_bank; fields=ppp_private_consumption, tax_rate_assumption, household_debt_proxy | AW4: https://api.worldbank.org/v2/country/MYS/indicator/SI.POV.GINI?format=json&mrv=30 | AX4: Tier 3 | AY4: 2021-12-31 | AZ4: providers=world_bank; fields=gini_coefficient | BE4: https://api.worldbank.org/v2/country/MYS/indicator/NY.GDP.PCAP.PP.CD?format=json&mrv=30 | https://api.worldbank.org/v2/country/MYS/indicator/NY.GDP.MKTP.KD.ZG?format=json&mrv=30 | BF4: Tier 3 | BG4: 2024-12-31 | BH4: providers=world_bank; fields=gdp_per_capita_ppp, gdp_growth
A5: id-jakarta | B5: Jakarta | C5: Indonesia | D5: Southeast Asia | E5: primary | F5: provisional | M5: =IF(OR($G5="",$H5="",$I5="",$J5="",$K5="",$L5="",$AL5="",$AM5=""),"",((($G5*(1-$AM5))-$H5-$I5-$J5-$K5-$L5)/$AL5)) | P5: =IF($O5<>"",$O5,$AN5) | AI5: =IFERROR(INDEX(Country_Context!$B$2:$B$64,MATCH($C5,Country_Context!$A$2:$A$64,0)),"") | AJ5: =IFERROR(INDEX(Country_Context!$C$2:$C$64,MATCH($C5,Country_Context!$A$2:$A$64,0)),"") | AK5: =IFERROR(INDEX(Country_Context!$D$2:$D$64,MATCH($C5,Country_Context!$A$2:$A$64,0)),"") | AL5: =IFERROR(INDEX(Country_Context!$E$2:$E$64,MATCH($C5,Country_Context!$A$2:$A$64,0)),"") | AM5: =IFERROR(INDEX(Country_Context!$F$2:$F$64,MATCH($C5,Country_Context!$A$2:$A$64,0)),"") | AN5: =IFERROR(INDEX(Country_Context!$G$2:$G$64,MATCH($C5,Country_Context!$A$2:$A$64,0)),"") | AO5: https://api.worldbank.org/v2/country/IDN/indicator/PA.NUS.PRVT.PP?format=json&mrv=30 | https://api.worldbank.org/v2/country/IDN/indicator/GC.TAX.TOTL.GD.ZS?format=json&mrv=30 | https://api.worldbank.org/v2/country/IDN/indicator/FD.AST.PRVT.GD.ZS?format=json&mrv=30 | AP5: Tier 3 | AQ5: 2024-12-31 | AR5: providers=world_bank; fields=ppp_private_consumption, tax_rate_assumption, household_debt_proxy | AW5: https://api.worldbank.org/v2/country/IDN/indicator/SI.POV.GINI?format=json&mrv=30 | AX5: Tier 3 | AY5: 2024-12-31 | AZ5: providers=world_bank; fields=gini_coefficient | BE5: https://api.worldbank.org/v2/country/IDN/indicator/NY.GDP.PCAP.PP.CD?format=json&mrv=30 | https://api.worldbank.org/v2/country/IDN/indicator/NY.GDP.MKTP.KD.ZG?format=json&mrv=30 | BF5: Tier 3 | BG5: 2024-12-31 | BH5: providers=world_bank; fields=gdp_per_capita_ppp, gdp_growth
A6: ph-makati | B6: Makati | C6: Philippines | D6: Southeast Asia | E6: primary | F6: provisional | M6: =IF(OR($G6="",$H6="",$I6="",$J6="",$K6="",$L6="",$AL6="",$AM6=""),"",((($G6*(1-$AM6))-$H6-$I6-$J6-$K6-$L6)/$AL6)) | P6: =IF($O6<>"",$O6,$AN6) | AI6: =IFERROR(INDEX(Country_Context!$B$2:$B$64,MATCH($C6,Country_Context!$A$2:$A$64,0)),"") | AJ6: =IFERROR(INDEX(Country_Context!$C$2:$C$64,MATCH($C6,Country_Context!$A$2:$A$64,0)),"") | AK6: =IFERROR(INDEX(Country_Context!$D$2:$D$64,MATCH($C6,Country_Context!$A$2:$A$64,0)),"") | AL6: =IFERROR(INDEX(Country_Context!$E$2:$E$64,MATCH($C6,Country_Context!$A$2:$A$64,0)),"") | AM6: =IFERROR(INDEX(Country_Context!$F$2:$F$64,MATCH($C6,Country_Context!$A$2:$A$64,0)),"") | AN6: =IFERROR(INDEX(Country_Context!$G$2:$G$64,MATCH($C6,Country_Context!$A$2:$A$64,0)),"") | AO6: https://api.worldbank.org/v2/country/PHL/indicator/PA.NUS.PRVT.PP?format=json&mrv=30 | https://api.worldbank.org/v2/country/PHL/indicator/GC.TAX.TOTL.GD.ZS?format=json&mrv=30 | https://api.worldbank.org/v2/country/PHL/indicator/FD.AST.PRVT.GD.ZS?format=json&mrv=30 | AP6: Tier 3 | AQ6: 2024-12-31 | AR6: providers=world_bank; fields=ppp_private_consumption, tax_rate_assumption, household_debt_proxy | AW6: https://api.worldbank.org/v2/country/PHL/indicator/SI.POV.GINI?format=json&mrv=30 | AX6: Tier 3 | AY6: 2023-12-31 | AZ6: providers=world_bank; fields=gini_coefficient | BE6: https://api.worldbank.org/v2/country/PHL/indicator/NY.GDP.PCAP.PP.CD?format=json&mrv=30 | https://api.worldbank.org/v2/country/PHL/indicator/NY.GDP.MKTP.KD.ZG?format=json&mrv=30 | BF6: Tier 3 | BG6: 2024-12-31 | BH6: providers=world_bank; fields=gdp_per_capita_ppp, gdp_growth
A7: my-george-town | B7: George Town | C7: Malaysia | D7: Southeast Asia | E7: secondary | F7: locked | M7: =IF(OR($G7="",$H7="",$I7="",$J7="",$K7="",$L7="",$AL7="",$AM7=""),"",((($G7*(1-$AM7))-$H7-$I7-$J7-$K7-$L7)/$AL7)) | P7: =IF($O7<>"",$O7,$AN7) | AI7: =IFERROR(INDEX(Country_Context!$B$2:$B$64,MATCH($C7,Country_Context!$A$2:$A$64,0)),"") | AJ7: =IFERROR(INDEX(Country_Context!$C$2:$C$64,MATCH($C7,Country_Context!$A$2:$A$64,0)),"") | AK7: =IFERROR(INDEX(Country_Context!$D$2:$D$64,MATCH($C7,Country_Context!$A$2:$A$64,0)),"") | AL7: =IFERROR(INDEX(Country_Context!$E$2:$E$64,MATCH($C7,Country_Context!$A$2:$A$64,0)),"") | AM7: =IFERROR(INDEX(Country_Context!$F$2:$F$64,MATCH($C7,Country_Context!$A$2:$A$64,0)),"") | AN7: =IFERROR(INDEX(Country_Context!$G$2:$G$64,MATCH($C7,Country_Context!$A$2:$A$64,0)),"") | AO7: https://api.worldbank.org/v2/country/MYS/indicator/PA.NUS.PRVT.PP?format=json&mrv=30 | https://api.worldbank.org/v2/country/MYS/indicator/GC.TAX.TOTL.GD.ZS?format=json&mrv=30 | https://api.worldbank.org/v2/country/MYS/indicator/FD.AST.PRVT.GD.ZS?format=json&mrv=30 | AP7: Tier 3 | AQ7: 2024-12-31 | AR7: providers=world_bank; fields=ppp_private_consumption, tax_rate_assumption, household_debt_proxy | AW7: https://api.worldbank.org/v2/country/MYS/indicator/SI.POV.GINI?format=json&mrv=30 | AX7: Tier 3 | AY7: 2021-12-31 | AZ7: providers=world_bank; fields=gini_coefficient | BE7: https://api.worldbank.org/v2/country/MYS/indicator/NY.GDP.PCAP.PP.CD?format=json&mrv=30 | https://api.worldbank.org/v2/country/MYS/indicator/NY.GDP.MKTP.KD.ZG?format=json&mrv=30 | BF7: Tier 3 | BG7: 2024-12-31 | BH7: providers=world_bank; fields=gdp_per_capita_ppp, gdp_growth
A8: th-phuket | B8: Phuket | C8: Thailand | D8: Southeast Asia | E8: secondary | F8: locked | M8: =IF(OR($G8="",$H8="",$I8="",$J8="",$K8="",$L8="",$AL8="",$AM8=""),"",((($G8*(1-$AM8))-$H8-$I8-$J8-$K8-$L8)/$AL8)) | P8: =IF($O8<>"",$O8,$AN8) | AI8: =IFERROR(INDEX(Country_Context!$B$2:$B$64,MATCH($C8,Country_Context!$A$2:$A$64,0)),"") | AJ8: =IFERROR(INDEX(Country_Context!$C$2:$C$64,MATCH($C8,Country_Context!$A$2:$A$64,0)),"") | AK8: =IFERROR(INDEX(Country_Context!$D$2:$D$64,MATCH($C8,Country_Context!$A$2:$A$64,0)),"") | AL8: =IFERROR(INDEX(Country_Context!$E$2:$E$64,MATCH($C8,Country_Context!$A$2:$A$64,0)),"") | AM8: =IFERROR(INDEX(Country_Context!$F$2:$F$64,MATCH($C8,Country_Context!$A$2:$A$64,0)),"") | AN8: =IFERROR(INDEX(Country_Context!$G$2:$G$64,MATCH($C8,Country_Context!$A$2:$A$64,0)),"") | AO8: https://api.worldbank.org/v2/country/THA/indicator/PA.NUS.PRVT.PP?format=json&mrv=30 | https://api.worldbank.org/v2/country/THA/indicator/GC.TAX.TOTL.GD.ZS?format=json&mrv=30 | https://api.worldbank.org/v2/country/THA/indicator/FD.AST.PRVT.GD.ZS?format=json&mrv=30 | AP8: Tier 3 | AQ8: 2024-12-31 | AR8: providers=world_bank; fields=ppp_private_consumption, tax_rate_assumption, household_debt_proxy | AW8: https://api.worldbank.org/v2/country/THA/indicator/SI.POV.GINI?format=json&mrv=30 | AX8: Tier 3 | AY8: 2023-12-31 | AZ8: providers=world_bank; fields=gini_coefficient | BE8: https://api.worldbank.org/v2/country/THA/indicator/NY.GDP.PCAP.PP.CD?format=json&mrv=30 | https://api.worldbank.org/v2/country/THA/indicator/NY.GDP.MKTP.KD.ZG?format=json&mrv=30 | BF8: Tier 3 | BG8: 2024-12-31 | BH8: providers=world_bank; fields=gdp_per_capita_ppp, gdp_growth
A9: th-chiang-mai | B9: Chiang Mai | C9: Thailand | D9: Southeast Asia | E9: secondary | F9: locked | M9: =IF(OR($G9="",$H9="",$I9="",$J9="",$K9="",$L9="",$AL9="",$AM9=""),"",((($G9*(1-$AM9))-$H9-$I9-$J9-$K9-$L9)/$AL9)) | P9: =IF($O9<>"",$O9,$AN9) | AI9: =IFERROR(INDEX(Country_Context!$B$2:$B$64,MATCH($C9,Country_Context!$A$2:$A$64,0)),"") | AJ9: =IFERROR(INDEX(Country_Context!$C$2:$C$64,MATCH($C9,Country_Context!$A$2:$A$64,0)),"") | AK9: =IFERROR(INDEX(Country_Context!$D$2:$D$64,MATCH($C9,Country_Context!$A$2:$A$64,0)),"") | AL9: =IFERROR(INDEX(Country_Context!$E$2:$E$64,MATCH($C9,Country_Context!$A$2:$A$64,0)),"") | AM9: =IFERROR(INDEX(Country_Context!$F$2:$F$64,MATCH($C9,Country_Context!$A$2:$A$64,0)),"") | AN9: =IFERROR(INDEX(Country_Context!$G$2:$G$64,MATCH($C9,Country_Context!$A$2:$A$64,0)),"") | AO9: https://api.worldbank.org/v2/country/THA/indicator/PA.NUS.PRVT.PP?format=json&mrv=30 | https://api.worldbank.org/v2/country/THA/indicator/GC.TAX.TOTL.GD.ZS?format=json&mrv=30 | https://api.worldbank.org/v2/country/THA/indicator/FD.AST.PRVT.GD.ZS?format=json&mrv=30 | AP9: Tier 3 | AQ9: 2024-12-31 | AR9: providers=world_bank; fields=ppp_private_consumption, tax_rate_assumption, household_debt_proxy | AW9: https://api.worldbank.org/v2/country/THA/indicator/SI.POV.GINI?format=json&mrv=30 | AX9: Tier 3 | AY9: 2023-12-31 | AZ9: providers=world_bank; fields=gini_coefficient | BE9: https://api.worldbank.org/v2/country/THA/indicator/NY.GDP.PCAP.PP.CD?format=json&mrv=30 | https://api.worldbank.org/v2/country/THA/indicator/NY.GDP.MKTP.KD.ZG?format=json&mrv=30 | BF9: Tier 3 | BG9: 2024-12-31 | BH9: providers=world_bank; fields=gdp_per_capita_ppp, gdp_growth
A10: my-kuching | B10: Kuching | C10: Malaysia | D10: Southeast Asia | E10: secondary | F10: locked | M10: =IF(OR($G10="",$H10="",$I10="",$J10="",$K10="",$L10="",$AL10="",$AM10=""),"",((($G10*(1-$AM10))-$H10-$I10-$J10-$K10-$L10)/$AL10)) | P10: =IF($O10<>"",$O10,$AN10) | AI10: =IFERROR(INDEX(Country_Context!$B$2:$B$64,MATCH($C10,Country_Context!$A$2:$A$64,0)),"") | AJ10: =IFERROR(INDEX(Country_Context!$C$2:$C$64,MATCH($C10,Country_Context!$A$2:$A$64,0)),"") | AK10: =IFERROR(INDEX(Country_Context!$D$2:$D$64,MATCH($C10,Country_Context!$A$2:$A$64,0)),"") | AL10: =IFERROR(INDEX(Country_Context!$E$2:$E$64,MATCH($C10,Country_Context!$A$2:$A$64,0)),"") | AM10: =IFERROR(INDEX(Country_Context!$F$2:$F$64,MATCH($C10,Country_Context!$A$2:$A$64,0)),"") | AN10: =IFERROR(INDEX(Country_Context!$G$2:$G$64,MATCH($C10,Country_Context!$A$2:$A$64,0)),"") | AO10: https://api.worldbank.org/v2/country/MYS/indicator/PA.NUS.PRVT.PP?format=json&mrv=30 | https://api.worldbank.org/v2/country/MYS/indicator/GC.TAX.TOTL.GD.ZS?format=json&mrv=30 | https://api.worldbank.org/v2/country/MYS/indicator/FD.AST.PRVT.GD.ZS?format=json&mrv=30 | AP10: Tier 3 | AQ10: 2024-12-31 | AR10: providers=world_bank; fields=ppp_private_consumption, tax_rate_assumption, household_debt_proxy | AW10: https://api.worldbank.org/v2/country/MYS/indicator/SI.POV.GINI?format=json&mrv=30 | AX10: Tier 3 | AY10: 2021-12-31 | AZ10: providers=world_bank; fields=gini_coefficient | BE10: https://api.worldbank.org/v2/country/MYS/indicator/NY.GDP.PCAP.PP.CD?format=json&mrv=30 | https://api.worldbank.org/v2/country/MYS/indicator/NY.GDP.MKTP.KD.ZG?format=json&mrv=30 | BF10: Tier 3 | BG10: 2024-12-31 | BH10: providers=world_bank; fields=gdp_per_capita_ppp, gdp_growth
A11: th-hat-yai | B11: Hat Yai | C11: Thailand | D11: Southeast Asia | E11: secondary | F11: provisional | M11: =IF(OR($G11="",$H11="",$I11="",$J11="",$K11="",$L11="",$AL11="",$AM11=""),"",((($G11*(1-$AM11))-$H11-$I11-$J11-$K11-$L11)/$AL11)) | P11: =IF($O11<>"",$O11,$AN11) | AI11: =IFERROR(INDEX(Country_Context!$B$2:$B$64,MATCH($C11,Country_Context!$A$2:$A$64,0)),"") | AJ11: =IFERROR(INDEX(Country_Context!$C$2:$C$64,MATCH($C11,Country_Context!$A$2:$A$64,0)),"") | AK11: =IFERROR(INDEX(Country_Context!$D$2:$D$64,MATCH($C11,Country_Context!$A$2:$A$64,0)),"") | AL11: =IFERROR(INDEX(Country_Context!$E$2:$E$64,MATCH($C11,Country_Context!$A$2:$A$64,0)),"") | AM11: =IFERROR(INDEX(Country_Context!$F$2:$F$64,MATCH($C11,Country_Context!$A$2:$A$64,0)),"") | AN11: =IFERROR(INDEX(Country_Context!$G$2:$G$64,MATCH($C11,Country_Context!$A$2:$A$64,0)),"") | AO11: https://api.worldbank.org/v2/country/THA/indicator/PA.NUS.PRVT.PP?format=json&mrv=30 | https://api.worldbank.org/v2/country/THA/indicator/GC.TAX.TOTL.GD.ZS?format=json&mrv=30 | https://api.worldbank.org/v2/country/THA/indicator/FD.AST.PRVT.GD.ZS?format=json&mrv=30 | AP11: Tier 3 | AQ11: 2024-12-31 | AR11: providers=world_bank; fields=ppp_private_consumption, tax_rate_assumption, household_debt_proxy | AW11: https://api.worldbank.org/v2/country/THA/indicator/SI.POV.GINI?format=json&mrv=30 | AX11: Tier 3 | AY11: 2023-12-31 | AZ11: providers=world_bank; fields=gini_coefficient | BE11: https://api.worldbank.org/v2/country/THA/indicator/NY.GDP.PCAP.PP.CD?format=json&mrv=30 | https://api.worldbank.org/v2/country/THA/indicator/NY.GDP.MKTP.KD.ZG?format=json&mrv=30 | BF11: Tier 3 | BG11: 2024-12-31 | BH11: providers=world_bank; fields=gdp_per_capita_ppp, gdp_growth
A12: tw-taipei | B12: Taipei | C12: Taiwan | D12: East Asia | E12: primary | F12: locked | M12: =IF(OR($G12="",$H12="",$I12="",$J12="",$K12="",$L12="",$AL12="",$AM12=""),"",((($G12*(1-$AM12))-$H12-$I12-$J12-$K12-$L12)/$AL12)) | P12: =IF($O12<>"",$O12,$AN12) | AI12: =IFERROR(INDEX(Country_Context!$B$2:$B$64,MATCH($C12,Country_Context!$A$2:$A$64,0)),"") | AJ12: =IFERROR(INDEX(Country_Context!$C$2:$C$64,MATCH($C12,Country_Context!$A$2:$A$64,0)),"") | AK12: =IFERROR(INDEX(Country_Context!$D$2:$D$64,MATCH($C12,Country_Context!$A$2:$A$64,0)),"") | AL12: =IFERROR(INDEX(Country_Context!$E$2:$E$64,MATCH($C12,Country_Context!$A$2:$A$64,0)),"") | AM12: =IFERROR(INDEX(Country_Context!$F$2:$F$64,MATCH($C12,Country_Context!$A$2:$A$64,0)),"") | AN12: =IFERROR(INDEX(Country_Context!$G$2:$G$64,MATCH($C12,Country_Context!$A$2:$A$64,0)),"")
A13: kr-busan | B13: Busan | C13: South Korea | D13: East Asia | E13: primary | F13: locked | M13: =IF(OR($G13="",$H13="",$I13="",$J13="",$K13="",$L13="",$AL13="",$AM13=""),"",((($G13*(1-$AM13))-$H13-$I13-$J13-$K13-$L13)/$AL13)) | P13: =IF($O13<>"",$O13,$AN13) | AI13: =IFERROR(INDEX(Country_Context!$B$2:$B$64,MATCH($C13,Country_Context!$A$2:$A$64,0)),"") | AJ13: =IFERROR(INDEX(Country_Context!$C$2:$C$64,MATCH($C13,Country_Context!$A$2:$A$64,0)),"") | AK13: =IFERROR(INDEX(Country_Context!$D$2:$D$64,MATCH($C13,Country_Context!$A$2:$A$64,0)),"") | AL13: =IFERROR(INDEX(Country_Context!$E$2:$E$64,MATCH($C13,Country_Context!$A$2:$A$64,0)),"") | AM13: =IFERROR(INDEX(Country_Context!$F$2:$F$64,MATCH($C13,Country_Context!$A$2:$A$64,0)),"") | AN13: =IFERROR(INDEX(Country_Context!$G$2:$G$64,MATCH($C13,Country_Context!$A$2:$A$64,0)),"") | AO13: https://api.worldbank.org/v2/country/KOR/indicator/PA.NUS.PRVT.PP?format=json&mrv=30 | https://api.worldbank.org/v2/country/KOR/indicator/GC.TAX.TOTL.GD.ZS?format=json&mrv=30 | https://api.worldbank.org/v2/country/KOR/indicator/FD.AST.PRVT.GD.ZS?format=json&mrv=30 | AP13: Tier 3 | AQ13: 2024-12-31 | AR13: providers=world_bank; fields=ppp_private_consumption, tax_rate_assumption, household_debt_proxy | AW13: https://api.worldbank.org/v2/country/KOR/indicator/SI.POV.GINI?format=json&mrv=30 | AX13: Tier 3 | AY13: 2021-12-31 | AZ13: providers=world_bank; fields=gini_coefficient | BE13: https://api.worldbank.org/v2/country/KOR/indicator/NY.GDP.PCAP.PP.CD?format=json&mrv=30 | https://api.worldbank.org/v2/country/KOR/indicator/NY.GDP.MKTP.KD.ZG?format=json&mrv=30 | BF13: Tier 3 | BG13: 2024-12-31 | BH13: providers=world_bank; fields=gdp_per_capita_ppp, gdp_growth
A14: cn-shanghai | B14: Shanghai | C14: China | D14: East Asia | E14: primary | F14: provisional | M14: =IF(OR($G14="",$H14="",$I14="",$J14="",$K14="",$L14="",$AL14="",$AM14=""),"",((($G14*(1-$AM14))-$H14-$I14-$J14-$K14-$L14)/$AL14)) | P14: =IF($O14<>"",$O14,$AN14) | AI14: =IFERROR(INDEX(Country_Context!$B$2:$B$64,MATCH($C14,Country_Context!$A$2:$A$64,0)),"") | AJ14: =IFERROR(INDEX(Country_Context!$C$2:$C$64,MATCH($C14,Country_Context!$A$2:$A$64,0)),"") | AK14: =IFERROR(INDEX(Country_Context!$D$2:$D$64,MATCH($C14,Country_Context!$A$2:$A$64,0)),"") | AL14: =IFERROR(INDEX(Country_Context!$E$2:$E$64,MATCH($C14,Country_Context!$A$2:$A$64,0)),"") | AM14: =IFERROR(INDEX(Country_Context!$F$2:$F$64,MATCH($C14,Country_Context!$A$2:$A$64,0)),"") | AN14: =IFERROR(INDEX(Country_Context!$G$2:$G$64,MATCH($C14,Country_Context!$A$2:$A$64,0)),"") | AO14: https://api.worldbank.org/v2/country/CHN/indicator/PA.NUS.PRVT.PP?format=json&mrv=30 | https://api.worldbank.org/v2/country/CHN/indicator/GC.TAX.TOTL.GD.ZS?format=json&mrv=30 | https://api.worldbank.org/v2/country/CHN/indicator/FD.AST.PRVT.GD.ZS?format=json&mrv=30 | AP14: Tier 3 | AQ14: 2024-12-31 | AR14: providers=world_bank; fields=ppp_private_consumption, tax_rate_assumption, household_debt_proxy | AW14: https://api.worldbank.org/v2/country/CHN/indicator/SI.POV.GINI?format=json&mrv=30 | AX14: Tier 3 | AY14: 2022-12-31 | AZ14: providers=world_bank; fields=gini_coefficient | BE14: https://api.worldbank.org/v2/country/CHN/indicator/NY.GDP.PCAP.PP.CD?format=json&mrv=30 | https://api.worldbank.org/v2/country/CHN/indicator/NY.GDP.MKTP.KD.ZG?format=json&mrv=30 | BF14: Tier 3 | BG14: 2024-12-31 | BH14: providers=world_bank; fields=gdp_per_capita_ppp, gdp_growth
